Workbook

Sheet README
A1: ERP RMI SOFULL - Import Template Pack
A2: Versi ini dibuat dari source code import aktif (UI CSV Preview -> Import).
A4: LANGKAH PAKAI
A5: 1) Isi data di sheet TEMPLATE_* sesuai kolom yang tersedia.
A6: 2) Kolom wajib ditandai header merah (required).
A7: 3) Kolom code/phone/npwp harus format Text untuk menjaga leading zero.
A8: 4) Gunakan dropdown jika tersedia (status/unit/office_code).
A9: 5) Cek sheet VALIDATION_RULES dan EXAMPLES sebelum export/upload.
A10: 6) Untuk upload ke sistem: gunakan CSV UTF-8 comma delimiter.
A12: Catatan penting:
A13: - Header untuk upload harus persis sesuai handler import.
A14: - Jangan ubah nama kolom.
... A25: employee_code boleh kosong (sistem auto-generate berdasarkan dept+join date).

Sheet TEMPLATE_MASTER_PRODUCTS
A1: sku | B1: products_name | C1: category | D1: unit | E1: status | F1: VALIDATION_ERROR
A2: SKU001 | B2: Produk Satu | C2: BMHP | D2: PCS | E2: active | F2: =IF(AND(A2<>"",B2<>"",OR(D2="",COUNTIF(LOOKUPS!$B$2:$B$100,D2)>0),OR(E2="",COUNTIF(LOOKUPS!$A$2:$A$100,E2)>0),ISNUMBER(SEARCH("@",E2&"@"))),"","ERROR: "&IF(A2="","sku wajib; ","")&IF(B2="","products_name wajib; ","")&IF(AND(D2<>"",COUNTIF(LOOKUPS!$B$2:$B$100,D2)=0),"unit tidak valid; ","")&IF(AND(E2<>"",COUNTIF(LOOKUPS!$A$2:$A$100,E2)=0),"status tidak valid; ",""))
A3: SKU002 | B3: Produk Dua | C3: ALKES | D3: PCS | E3: active | F3: =IF(AND(A3<>"",B3<>"",OR(D3="",COUNTIF(LOOKUPS!$B$2:$B$100,D3)>0),OR(E3="",COUNTIF(LOOKUPS!$A$2:$A$100,E3)>0),ISNUMBER(SEARCH("@",E3&"@"))),"","ERROR: "&IF(A3="","sku wajib; ","")&IF(B3="","products_name wajib; ","")&IF(AND(D3<>"",COUNTIF(LOOKUPS!$B$2:$B$100,D3)=0),"unit tidak valid; ","")&IF(AND(E3<>"",COUNTIF(LOOKUPS!$A$2:$A$100,E3)=0),"status tidak valid; ",""))
A4: SKU003 | B4: Produk Tiga | C4: BMHP | D4: BOX | E4: inactive | F4: =IF(AND(A4<>"",B4<>"",OR(D4="",COUNTIF(LOOKUPS!$B$2:$B$100,D4)>0),OR(E4="",COUNTIF(LOOKUPS!$A$2:$A$100,E4)>0),ISNUMBER(SEARCH("@",E4&"@"))),"","ERROR: "&IF(A4="","sku wajib; ","")&IF(B4="","products_name wajib; ","")&IF(AND(D4<>"",COUNTIF(LOOKUPS!$B$2:$B$100,D4)=0),"unit tidak valid; ","")&IF(AND(E4<>"",COUNTIF(LOOKUPS!$A$2:$A$100,E4)=0),"status tidak valid; ",""))
A5: SKU004 | B5: Produk Empat | C5: FARMASI | D5: UNIT | E5: active | F5: =IF(AND(A5<>"",B5<>"",OR(D5="",COUNTIF(LOOKUPS!$B$2:$B$100,D5)>0),OR(E5="",COUNTIF(LOOKUPS!$A$2:$A$100,E5)>0),ISNUMBER(SEARCH("@",E5&"@"))),"","ERROR: "&IF(A5="","sku wajib; ","")&IF(B5="","products_name wajib; ","")&IF(AND(D5<>"",COUNTIF(LOOKUPS!$B$2:$B$100,D5)=0),"unit tidak valid; ","")&IF(AND(E5<>"",COUNTIF(LOOKUPS!$A$2:$A$100,E5)=0),"status tidak valid; ",""))
A6: SKU005 | B6: Produk Lima | C6: BMHP | D6: CARTON | E6: active | F6: =IF(AND(A6<>"",B6<>"",OR(D6="",COUNTIF(LOOKUPS!$B$2:$B$100,D6)>0),OR(E6="",COUNTIF(LOOKUPS!$A$2:$A$100,E6)>0),ISNUMBER(SEARCH("@",E6&"@"))),"","ERROR: "&IF(A6="","sku wajib; ","")&IF(B6="","products_name wajib; ","")&IF(AND(D6<>"",COUNTIF(LOOKUPS!$B$2:$B$100,D6)=0),"unit tidak valid; ","")&IF(AND(E6<>"",COUNTIF(LOOKUPS!$A$2:$A$100,E6)=0),"status tidak valid; ",""))
F7: =IF(AND(A7<>"",B7<>"",OR(D7="",COUNTIF(LOOKUPS!$B$2:$B$100,D7)>0),OR(E7="",COUNTIF(LOOKUPS!$A$2:$A$100,E7)>0),ISNUMBER(SEARCH("@",E7&"@"))),"","ERROR: "&IF(A7="","sku wajib; ","")&IF(B7="","products_name wajib; ","")&IF(AND(D7<>"",COUNTIF(LOOKUPS!$B$2:$B$100,D7)=0),"unit tidak valid; ","")&IF(AND(E7<>"",COUNTIF(LOOKUPS!$A$2:$A$100,E7)=0),"status tidak valid; ",""))
F8: =IF(AND(A8<>"",B8<>"",OR(D8="",COUNTIF(LOOKUPS!$B$2:$B$100,D8)>0),OR(E8="",COUNTIF(LOOKUPS!$A$2:$A$100,E8)>0),ISNUMBER(SEARCH("@",E8&"@"))),"","ERROR: "&IF(A8="","sku wajib; ","")&IF(B8="","products_name wajib; ","")&IF(AND(D8<>"",COUNTIF(LOOKUPS!$B$2:$B$100,D8)=0),"unit tidak valid; ","")&IF(AND(E8<>"",COUNTIF(LOOKUPS!$A$2:$A$100,E8)=0),"status tidak valid; ",""))
F9: =IF(AND(A9<>"",B9<>"",OR(D9="",COUNTIF(LOOKUPS!$B$2:$B$100,D9)>0),OR(E9="",COUNTIF(LOOKUPS!$A$2:$A$100,E9)>0),ISNUMBER(SEARCH("@",E9&"@"))),"","ERROR: "&IF(A9="","sku wajib; ","")&IF(B9="","products_name wajib; ","")&IF(AND(D9<>"",COUNTIF(LOOKUPS!$B$2:$B$100,D9)=0),"unit tidak valid; ","")&IF(AND(E9<>"",COUNTIF(LOOKUPS!$A$2:$A$100,E9)=0),"status tidak valid; ",""))
F10: =IF(AND(A10<>"",B10<>"",OR(D10="",COUNTIF(LOOKUPS!$B$2:$B$100,D10)>0),OR(E10="",COUNTIF(LOOKUPS!$A$2:$A$100,E10)>0),ISNUMBER(SEARCH("@",E10&"@"))),"","ERROR: "&IF(A10="","sku wajib; ","")&IF(B10="","products_name wajib; ","")&IF(AND(D10<>"",COUNTIF(LOOKUPS!$B$2:$B$100,D10)=0),"unit tidak valid; ","")&IF(AND(E10<>"",COUNTIF(LOOKUPS!$A$2:$A$100,E10)=0),"status tidak valid; ",""))
F11: =IF(AND(A11<>"",B11<>"",OR(D11="",COUNTIF(LOOKUPS!$B$2:$B$100,D11)>0),OR(E11="",COUNTIF(LOOKUPS!$A$2:$A$100,E11)>0),ISNUMBER(SEARCH("@",E11&"@"))),"","ERROR: "&IF(A11="","sku wajib; ","")&IF(B11="","products_name wajib; ","")&IF(AND(D11<>"",COUNTIF(LOOKUPS!$B$2:$B$100,D11)=0),"unit tidak valid; ","")&IF(AND(E11<>"",COUNTIF(LOOKUPS!$A$2:$A$100,E11)=0),"status tidak valid; ",""))
F12: =IF(AND(A12<>"",B12<>"",OR(D12="",COUNTIF(LOOKUPS!$B$2:$B$100,D12)>0),OR(E12="",COUNTIF(LOOKUPS!$A$2:$A$100,E12)>0),ISNUMBER(SEARCH("@",E12&"@"))),"","ERROR: "&IF(A12="","sku wajib; ","")&IF(B12="","products_name wajib; ","")&IF(AND(D12<>"",COUNTIF(LOOKUPS!$B$2:$B$100,D12)=0),"unit tidak valid; ","")&IF(AND(E12<>"",COUNTIF(LOOKUPS!$A$2:$A$100,E12)=0),"status tidak valid; ",""))
F13: =IF(AND(A13<>"",B13<>"",OR(D13="",COUNTIF(LOOKUPS!$B$2:$B$100,D13)>0),OR(E13="",COUNTIF(LOOKUPS!$A$2:$A$100,E13)>0),ISNUMBER(SEARCH("@",E13&"@"))),"","ERROR: "&IF(A13="","sku wajib; ","")&IF(B13="","products_name wajib; ","")&IF(AND(D13<>"",COUNTIF(LOOKUPS!$B$2:$B$100,D13)=0),"unit tidak valid; ","")&IF(AND(E13<>"",COUNTIF(LOOKUPS!$A$2:$A$100,E13)=0),"status tidak valid; ",""))
F14: =IF(AND(A14<>"",B14<>"",OR(D14="",COUNTIF(LOOKUPS!$B$2:$B$100,D14)>0),OR(E14="",COUNTIF(LOOKUPS!$A$2:$A$100,E14)>0),ISNUMBER(SEARCH("@",E14&"@"))),"","ERROR: "&IF(A14="","sku wajib; ","")&IF(B14="","products_name wajib; ","")&IF(AND(D14<>"",COUNTIF(LOOKUPS!$B$2:$B$100,D14)=0),"unit tidak valid; ","")&IF(AND(E14<>"",COUNTIF(LOOKUPS!$A$2:$A$100,E14)=0),"status tidak valid; ",""))
F15: =IF(AND(A15<>"",B15<>"",OR(D15="",COUNTIF(LOOKUPS!$B$2:$B$100,D15)>0),OR(E15="",COUNTIF(LOOKUPS!$A$2:$A$100,E15)>0),ISNUMBER(SEARCH("@",E15&"@"))),"","ERROR: "&IF(A15="","sku wajib; ","")&IF(B15="","products_name wajib; ","")&IF(AND(D15<>"",COUNTIF(LOOKUPS!$B$2:$B$100,D15)=0),"unit tidak valid; ","")&IF(AND(E15<>"",COUNTIF(LOOKUPS!$A$2:$A$100,E15)=0),"status tidak valid; ",""))
F16: =IF(AND(A16<>"",B16<>"",OR(D16="",COUNTIF(LOOKUPS!$B$2:$B$100,D16)>0),OR(E16="",COUNTIF(LOOKUPS!$A$2:$A$100,E16)>0),ISNUMBER(SEARCH("@",E16&"@"))),"","ERROR: "&IF(A16="","sku wajib; ","")&IF(B16="","products_name wajib; ","")&IF(AND(D16<>"",COUNTIF(LOOKUPS!$B$2:$B$100,D16)=0),"unit tidak valid; ","")&IF(AND(E16<>"",COUNTIF(LOOKUPS!$A$2:$A$100,E16)=0),"status tidak valid; ",""))
F17: =IF(AND(A17<>"",B17<>"",OR(D17="",COUNTIF(LOOKUPS!$B$2:$B$100,D17)>0),OR(E17="",COUNTIF(LOOKUPS!$A$2:$A$100,E17)>0),ISNUMBER(SEARCH("@",E17&"@"))),"","ERROR: "&IF(A17="","sku wajib; ","")&IF(B17="","products_name wajib; ","")&IF(AND(D17<>"",COUNTIF(LOOKUPS!$B$2:$B$100,D17)=0),"unit tidak valid; ","")&IF(AND(E17<>"",COUNTIF(LOOKUPS!$A$2:$A$100,E17)=0),"status tidak valid; ",""))
F18: =IF(AND(A18<>"",B18<>"",OR(D18="",COUNTIF(LOOKUPS!$B$2:$B$100,D18)>0),OR(E18="",COUNTIF(LOOKUPS!$A$2:$A$100,E18)>0),ISNUMBER(SEARCH("@",E18&"@"))),"","ERROR: "&IF(A18="","sku wajib; ","")&IF(B18="","products_name wajib; ","")&IF(AND(D18<>"",COUNTIF(LOOKUPS!$B$2:$B$100,D18)=0),"unit tidak valid; ","")&IF(AND(E18<>"",COUNTIF(LOOKUPS!$A$2:$A$100,E18)=0),"status tidak valid; ",""))
... F2000: =IF(AND(A2000<>"",B2000<>"",OR(D2000="",COUNTIF(LOOKUPS!$B$2:$B$100,D2000)>0),OR(E2000="",COUNTIF(LOOKUPS!$A$2:$A$100,E2000)>0),ISNUMBER(SEARCH("@",E2000&"@"))),"","ERROR: "&IF(A2000="","sku wajib; ","")&IF(B2000="","products_name wajib; ","")&IF(AND(D2000<>"",COUNTIF(LOOKUPS!$B$2:$B$100,D2000)=0),"unit tidak valid; ","")&IF(AND(E2000<>"",COUNTIF(LOOKUPS!$A$2:$A$100,E2000)=0),"status tidak valid; ",""))

Sheet TEMPLATE_MASTER_CUSTOMERS
A1: customers_code | B1: customers_name | C1: category | D1: segment | E1: city | F1: office_code | G1: address | H1: phone | I1: email | J1: npwp | K1: status | L1: VALIDATION_ERROR
A2: CUST001 | B2: Customer Satu | C2: RS | D2: Hospital | E2: Bogor | F2: BGR | G2: Jl Contoh 1 | H2: 081200000001 | I2: csatu@example.com | J2: 01.234.567.8-999.000 | K2: active | L2: =IF(AND(A2<>"",B2<>"",OR(F2="",COUNTIF(LOOKUPS!$C$2:$C$100,F2)>0),OR(K2="",COUNTIF(LOOKUPS!$A$2:$A$100,K2)>0),OR(I2="",ISNUMBER(SEARCH("@",I2)))),"","ERROR: "&IF(A2="","customers_code wajib; ","")&IF(B2="","customers_name wajib; ","")&IF(AND(F2<>"",COUNTIF(LOOKUPS!$C$2:$C$100,F2)=0),"office_code tidak valid; ","")&IF(AND(K2<>"",COUNTIF(LOOKUPS!$A$2:$A$100,K2)=0),"status tidak valid; ","")&IF(AND(I2<>"",NOT(ISNUMBER(SEARCH("@",I2)))),"email tidak valid; ",""))
A3: CUST002 | B3: Customer Dua | C3: Klinik | D3: Clinic | E3: Jakarta | F3: JKT | G3: Jl Contoh 2 | H3: 081200000002 | I3: cdua@example.com | J3: 02.234.567.8-999.000 | K3: active | L3: =IF(AND(A3<>"",B3<>"",OR(F3="",COUNTIF(LOOKUPS!$C$2:$C$100,F3)>0),OR(K3="",COUNTIF(LOOKUPS!$A$2:$A$100,K3)>0),OR(I3="",ISNUMBER(SEARCH("@",I3)))),"","ERROR: "&IF(A3="","customers_code wajib; ","")&IF(B3="","customers_name wajib; ","")&IF(AND(F3<>"",COUNTIF(LOOKUPS!$C$2:$C$100,F3)=0),"office_code tidak valid; ","")&IF(AND(K3<>"",COUNTIF(LOOKUPS!$A$2:$A$100,K3)=0),"status tidak valid; ","")&IF(AND(I3<>"",NOT(ISNUMBER(SEARCH("@",I3)))),"email tidak valid; ",""))
A4: CUST003 | B4: Customer Tiga | C4: RS | D4: Hospital | E4: Depok | F4: DPK | G4: Jl Contoh 3 | H4: 081200000003 | I4: ctiga@example.com | J4: 03.234.567.8-999.000 | K4: inactive | L4: =IF(AND(A4<>"",B4<>"",OR(F4="",COUNTIF(LOOKUPS!$C$2:$C$100,F4)>0),OR(K4="",COUNTIF(LOOKUPS!$A$2:$A$100,K4)>0),OR(I4="",ISNUMBER(SEARCH("@",I4)))),"","ERROR: "&IF(A4="","customers_code wajib; ","")&IF(B4="","customers_name wajib; ","")&IF(AND(F4<>"",COUNTIF(LOOKUPS!$C$2:$C$100,F4)=0),"office_code tidak valid; ","")&IF(AND(K4<>"",COUNTIF(LOOKUPS!$A$2:$A$100,K4)=0),"status tidak valid; ","")&IF(AND(I4<>"",NOT(ISNUMBER(SEARCH("@",I4)))),"email tidak valid; ",""))
A5: CUST004 | B5: Customer Empat | C5: Apotek | D5: Retail | E5: Bandung | F5: BDG | G5: Jl Contoh 4 | H5: 081200000004 | I5: cempat@example.com | J5: 04.234.567.8-999.000 | K5: active | L5: =IF(AND(A5<>"",B5<>"",OR(F5="",COUNTIF(LOOKUPS!$C$2:$C$100,F5)>0),OR(K5="",COUNTIF(LOOKUPS!$A$2:$A$100,K5)>0),OR(I5="",ISNUMBER(SEARCH("@",I5)))),"","ERROR: "&IF(A5="","customers_code wajib; ","")&IF(B5="","customers_name wajib; ","")&IF(AND(F5<>"",COUNTIF(LOOKUPS!$C$2:$C$100,F5)=0),"office_code tidak valid; ","")&IF(AND(K5<>"",COUNTIF(LOOKUPS!$A$2:$A$100,K5)=0),"status tidak valid; ","")&IF(AND(I5<>"",NOT(ISNUMBER(SEARCH("@",I5)))),"email tidak valid; ",""))
A6: CUST005 | B6: Customer Lima | C6: Distributor | D6: B2B | E6: Surabaya | F6: SBY | G6: Jl Contoh 5 | H6: 081200000005 | I6: clima@example.com | J6: 05.234.567.8-999.000 | K6: active | L6: =IF(AND(A6<>"",B6<>"",OR(F6="",COUNTIF(LOOKUPS!$C$2:$C$100,F6)>0),OR(K6="",COUNTIF(LOOKUPS!$A$2:$A$100,K6)>0),OR(I6="",ISNUMBER(SEARCH("@",I6)))),"","ERROR: "&IF(A6="","customers_code wajib; ","")&IF(B6="","customers_name wajib; ","")&IF(AND(F6<>"",COUNTIF(LOOKUPS!$C$2:$C$100,F6)=0),"office_code tidak valid; ","")&IF(AND(K6<>"",COUNTIF(LOOKUPS!$A$2:$A$100,K6)=0),"status tidak valid; ","")&IF(AND(I6<>"",NOT(ISNUMBER(SEARCH("@",I6)))),"email tidak valid; ",""))
L7: =IF(AND(A7<>"",B7<>"",OR(F7="",COUNTIF(LOOKUPS!$C$2:$C$100,F7)>0),OR(K7="",COUNTIF(LOOKUPS!$A$2:$A$100,K7)>0),OR(I7="",ISNUMBER(SEARCH("@",I7)))),"","ERROR: "&IF(A7="","customers_code wajib; ","")&IF(B7="","customers_name wajib; ","")&IF(AND(F7<>"",COUNTIF(LOOKUPS!$C$2:$C$100,F7)=0),"office_code tidak valid; ","")&IF(AND(K7<>"",COUNTIF(LOOKUPS!$A$2:$A$100,K7)=0),"status tidak valid; ","")&IF(AND(I7<>"",NOT(ISNUMBER(SEARCH("@",I7)))),"email tidak valid; ",""))
L8: =IF(AND(A8<>"",B8<>"",OR(F8="",COUNTIF(LOOKUPS!$C$2:$C$100,F8)>0),OR(K8="",COUNTIF(LOOKUPS!$A$2:$A$100,K8)>0),OR(I8="",ISNUMBER(SEARCH("@",I8)))),"","ERROR: "&IF(A8="","customers_code wajib; ","")&IF(B8="","customers_name wajib; ","")&IF(AND(F8<>"",COUNTIF(LOOKUPS!$C$2:$C$100,F8)=0),"office_code tidak valid; ","")&IF(AND(K8<>"",COUNTIF(LOOKUPS!$A$2:$A$100,K8)=0),"status tidak valid; ","")&IF(AND(I8<>"",NOT(ISNUMBER(SEARCH("@",I8)))),"email tidak valid; ",""))
L9: =IF(AND(A9<>"",B9<>"",OR(F9="",COUNTIF(LOOKUPS!$C$2:$C$100,F9)>0),OR(K9="",COUNTIF(LOOKUPS!$A$2:$A$100,K9)>0),OR(I9="",ISNUMBER(SEARCH("@",I9)))),"","ERROR: "&IF(A9="","customers_code wajib; ","")&IF(B9="","customers_name wajib; ","")&IF(AND(F9<>"",COUNTIF(LOOKUPS!$C$2:$C$100,F9)=0),"office_code tidak valid; ","")&IF(AND(K9<>"",COUNTIF(LOOKUPS!$A$2:$A$100,K9)=0),"status tidak valid; ","")&IF(AND(I9<>"",NOT(ISNUMBER(SEARCH("@",I9)))),"email tidak valid; ",""))
L10: =IF(AND(A10<>"",B10<>"",OR(F10="",COUNTIF(LOOKUPS!$C$2:$C$100,F10)>0),OR(K10="",COUNTIF(LOOKUPS!$A$2:$A$100,K10)>0),OR(I10="",ISNUMBER(SEARCH("@",I10)))),"","ERROR: "&IF(A10="","customers_code wajib; ","")&IF(B10="","customers_name wajib; ","")&IF(AND(F10<>"",COUNTIF(LOOKUPS!$C$2:$C$100,F10)=0),"office_code tidak valid; ","")&IF(AND(K10<>"",COUNTIF(LOOKUPS!$A$2:$A$100,K10)=0),"status tidak valid; ","")&IF(AND(I10<>"",NOT(ISNUMBER(SEARCH("@",I10)))),"email tidak valid; ",""))
L11: =IF(AND(A11<>"",B11<>"",OR(F11="",COUNTIF(LOOKUPS!$C$2:$C$100,F11)>0),OR(K11="",COUNTIF(LOOKUPS!$A$2:$A$100,K11)>0),OR(I11="",ISNUMBER(SEARCH("@",I11)))),"","ERROR: "&IF(A11="","customers_code wajib; ","")&IF(B11="","customers_name wajib; ","")&IF(AND(F11<>"",COUNTIF(LOOKUPS!$C$2:$C$100,F11)=0),"office_code tidak valid; ","")&IF(AND(K11<>"",COUNTIF(LOOKUPS!$A$2:$A$100,K11)=0),"status tidak valid; ","")&IF(AND(I11<>"",NOT(ISNUMBER(SEARCH("@",I11)))),"email tidak valid; ",""))
L12: =IF(AND(A12<>"",B12<>"",OR(F12="",COUNTIF(LOOKUPS!$C$2:$C$100,F12)>0),OR(K12="",COUNTIF(LOOKUPS!$A$2:$A$100,K12)>0),OR(I12="",ISNUMBER(SEARCH("@",I12)))),"","ERROR: "&IF(A12="","customers_code wajib; ","")&IF(B12="","customers_name wajib; ","")&IF(AND(F12<>"",COUNTIF(LOOKUPS!$C$2:$C$100,F12)=0),"office_code tidak valid; ","")&IF(AND(K12<>"",COUNTIF(LOOKUPS!$A$2:$A$100,K12)=0),"status tidak valid; ","")&IF(AND(I12<>"",NOT(ISNUMBER(SEARCH("@",I12)))),"email tidak valid; ",""))
L13: =IF(AND(A13<>"",B13<>"",OR(F13="",COUNTIF(LOOKUPS!$C$2:$C$100,F13)>0),OR(K13="",COUNTIF(LOOKUPS!$A$2:$A$100,K13)>0),OR(I13="",ISNUMBER(SEARCH("@",I13)))),"","ERROR: "&IF(A13="","customers_code wajib; ","")&IF(B13="","customers_name wajib; ","")&IF(AND(F13<>"",COUNTIF(LOOKUPS!$C$2:$C$100,F13)=0),"office_code tidak valid; ","")&IF(AND(K13<>"",COUNTIF(LOOKUPS!$A$2:$A$100,K13)=0),"status tidak valid; ","")&IF(AND(I13<>"",NOT(ISNUMBER(SEARCH("@",I13)))),"email tidak valid; ",""))
L14: =IF(AND(A14<>"",B14<>"",OR(F14="",COUNTIF(LOOKUPS!$C$2:$C$100,F14)>0),OR(K14="",COUNTIF(LOOKUPS!$A$2:$A$100,K14)>0),OR(I14="",ISNUMBER(SEARCH("@",I14)))),"","ERROR: "&IF(A14="","customers_code wajib; ","")&IF(B14="","customers_name wajib; ","")&IF(AND(F14<>"",COUNTIF(LOOKUPS!$C$2:$C$100,F14)=0),"office_code tidak valid; ","")&IF(AND(K14<>"",COUNTIF(LOOKUPS!$A$2:$A$100,K14)=0),"status tidak valid; ","")&IF(AND(I14<>"",NOT(ISNUMBER(SEARCH("@",I14)))),"email tidak valid; ",""))
L15: =IF(AND(A15<>"",B15<>"",OR(F15="",COUNTIF(LOOKUPS!$C$2:$C$100,F15)>0),OR(K15="",COUNTIF(LOOKUPS!$A$2:$A$100,K15)>0),OR(I15="",ISNUMBER(SEARCH("@",I15)))),"","ERROR: "&IF(A15="","customers_code wajib; ","")&IF(B15="","customers_name wajib; ","")&IF(AND(F15<>"",COUNTIF(LOOKUPS!$C$2:$C$100,F15)=0),"office_code tidak valid; ","")&IF(AND(K15<>"",COUNTIF(LOOKUPS!$A$2:$A$100,K15)=0),"status tidak valid; ","")&IF(AND(I15<>"",NOT(ISNUMBER(SEARCH("@",I15)))),"email tidak valid; ",""))
L16: =IF(AND(A16<>"",B16<>"",OR(F16="",COUNTIF(LOOKUPS!$C$2:$C$100,F16)>0),OR(K16="",COUNTIF(LOOKUPS!$A$2:$A$100,K16)>0),OR(I16="",ISNUMBER(SEARCH("@",I16)))),"","ERROR: "&IF(A16="","customers_code wajib; ","")&IF(B16="","customers_name wajib; ","")&IF(AND(F16<>"",COUNTIF(LOOKUPS!$C$2:$C$100,F16)=0),"office_code tidak valid; ","")&IF(AND(K16<>"",COUNTIF(LOOKUPS!$A$2:$A$100,K16)=0),"status tidak valid; ","")&IF(AND(I16<>"",NOT(ISNUMBER(SEARCH("@",I16)))),"email tidak valid; ",""))
L17: =IF(AND(A17<>"",B17<>"",OR(F17="",COUNTIF(LOOKUPS!$C$2:$C$100,F17)>0),OR(K17="",COUNTIF(LOOKUPS!$A$2:$A$100,K17)>0),OR(I17="",ISNUMBER(SEARCH("@",I17)))),"","ERROR: "&IF(A17="","customers_code wajib; ","")&IF(B17="","customers_name wajib; ","")&IF(AND(F17<>"",COUNTIF(LOOKUPS!$C$2:$C$100,F17)=0),"office_code tidak valid; ","")&IF(AND(K17<>"",COUNTIF(LOOKUPS!$A$2:$A$100,K17)=0),"status tidak valid; ","")&IF(AND(I17<>"",NOT(ISNUMBER(SEARCH("@",I17)))),"email tidak valid; ",""))
L18: =IF(AND(A18<>"",B18<>"",OR(F18="",COUNTIF(LOOKUPS!$C$2:$C$100,F18)>0),OR(K18="",COUNTIF(LOOKUPS!$A$2:$A$100,K18)>0),OR(I18="",ISNUMBER(SEARCH("@",I18)))),"","ERROR: "&IF(A18="","customers_code wajib; ","")&IF(B18="","customers_name wajib; ","")&IF(AND(F18<>"",COUNTIF(LOOKUPS!$C$2:$C$100,F18)=0),"office_code tidak valid; ","")&IF(AND(K18<>"",COUNTIF(LOOKUPS!$A$2:$A$100,K18)=0),"status tidak valid; ","")&IF(AND(I18<>"",NOT(ISNUMBER(SEARCH("@",I18)))),"email tidak valid; ",""))
... L2000: =IF(AND(A2000<>"",B2000<>"",OR(F2000="",COUNTIF(LOOKUPS!$C$2:$C$100,F2000)>0),OR(K2000="",COUNTIF(LOOKUPS!$A$2:$A$100,K2000)>0),OR(I2000="",ISNUMBER(SEARCH("@",I2000)))),"","ERROR: "&IF(A2000="","customers_code wajib; ","")&IF(B2000="","customers_name wajib; ","")&IF(AND(F2000<>"",COUNTIF(LOOKUPS!$C$2:$C$100,F2000)=0),"office_code tidak valid; ","")&IF(AND(K2000<>"",COUNTIF(LOOKUPS!$A$2:$A$100,K2000)=0),"status tidak valid; ","")&IF(AND(I2000<>"",NOT(ISNUMBER(SEARCH("@",I2000)))),"email tidak valid; ",""))

Sheet TEMPLATE_MASTER_VENDORS
A1: vendors_code | B1: vendors_name | C1: vendor_type | D1: city | E1: phone | F1: email | G1: npwp | H1: status | I1: VALIDATION_ERROR
A2: VEND001 | B2: PT Vendor Satu | C2: Forwarding | D2: Jakarta | E2: 0211112222 | F2: vendor1@example.com | G2: 01.111.222.3-444.000 | H2: active | I2: =IF(AND(A2<>"",B2<>"",OR(H2="",COUNTIF(LOOKUPS!$A$2:$A$100,H2)>0),OR(F2="",ISNUMBER(SEARCH("@",F2)))),"","ERROR: "&IF(A2="","vendors_code wajib; ","")&IF(B2="","vendors_name wajib; ","")&IF(AND(H2<>"",COUNTIF(LOOKUPS!$A$2:$A$100,H2)=0),"status tidak valid; ","")&IF(AND(F2<>"",NOT(ISNUMBER(SEARCH("@",F2)))),"email tidak valid; ",""))
A3: VEND002 | B3: PT Vendor Dua | C3: Logistic/Expedisi | D3: Surabaya | E3: 0311112222 | F3: vendor2@example.com | G3: 02.111.222.3-444.000 | H3: active | I3: =IF(AND(A3<>"",B3<>"",OR(H3="",COUNTIF(LOOKUPS!$A$2:$A$100,H3)>0),OR(F3="",ISNUMBER(SEARCH("@",F3)))),"","ERROR: "&IF(A3="","vendors_code wajib; ","")&IF(B3="","vendors_name wajib; ","")&IF(AND(H3<>"",COUNTIF(LOOKUPS!$A$2:$A$100,H3)=0),"status tidak valid; ","")&IF(AND(F3<>"",NOT(ISNUMBER(SEARCH("@",F3)))),"email tidak valid; ",""))
A4: VEND003 | B4: PT Vendor Tiga | C4: Lainnya | D4: Bandung | E4: 0221112222 | F4: vendor3@example.com | G4: 03.111.222.3-444.000 | H4: inactive | I4: =IF(AND(A4<>"",B4<>"",OR(H4="",COUNTIF(LOOKUPS!$A$2:$A$100,H4)>0),OR(F4="",ISNUMBER(SEARCH("@",F4)))),"","ERROR: "&IF(A4="","vendors_code wajib; ","")&IF(B4="","vendors_name wajib; ","")&IF(AND(H4<>"",COUNTIF(LOOKUPS!$A$2:$A$100,H4)=0),"status tidak valid; ","")&IF(AND(F4<>"",NOT(ISNUMBER(SEARCH("@",F4)))),"email tidak valid; ",""))
A5: VEND004 | B5: PT Vendor Empat | C5: Principal | D5: Bogor | E5: 0251112222 | F5: vendor4@example.com | G5: 04.111.222.3-444.000 | H5: active | I5: =IF(AND(A5<>"",B5<>"",OR(H5="",COUNTIF(LOOKUPS!$A$2:$A$100,H5)>0),OR(F5="",ISNUMBER(SEARCH("@",F5)))),"","ERROR: "&IF(A5="","vendors_code wajib; ","")&IF(B5="","vendors_name wajib; ","")&IF(AND(H5<>"",COUNTIF(LOOKUPS!$A$2:$A$100,H5)=0),"status tidak valid; ","")&IF(AND(F5<>"",NOT(ISNUMBER(SEARCH("@",F5)))),"email tidak valid; ",""))
A6: VEND005 | B6: PT Vendor Lima | C6: Distributor | D6: Depok | E6: 0213334444 | F6: vendor5@example.com | G6: 05.111.222.3-444.000 | H6: active | I6: =IF(AND(A6<>"",B6<>"",OR(H6="",COUNTIF(LOOKUPS!$A$2:$A$100,H6)>0),OR(F6="",ISNUMBER(SEARCH("@",F6)))),"","ERROR: "&IF(A6="","vendors_code wajib; ","")&IF(B6="","vendors_name wajib; ","")&IF(AND(H6<>"",COUNTIF(LOOKUPS!$A$2:$A$100,H6)=0),"status tidak valid; ","")&IF(AND(F6<>"",NOT(ISNUMBER(SEARCH("@",F6)))),"email tidak valid; ",""))
I7: =IF(AND(A7<>"",B7<>"",OR(H7="",COUNTIF(LOOKUPS!$A$2:$A$100,H7)>0),OR(F7="",ISNUMBER(SEARCH("@",F7)))),"","ERROR: "&IF(A7="","vendors_code wajib; ","")&IF(B7="","vendors_name wajib; ","")&IF(AND(H7<>"",COUNTIF(LOOKUPS!$A$2:$A$100,H7)=0),"status tidak valid; ","")&IF(AND(F7<>"",NOT(ISNUMBER(SEARCH("@",F7)))),"email tidak valid; ",""))
I8: =IF(AND(A8<>"",B8<>"",OR(H8="",COUNTIF(LOOKUPS!$A$2:$A$100,H8)>0),OR(F8="",ISNUMBER(SEARCH("@",F8)))),"","ERROR: "&IF(A8="","vendors_code wajib; ","")&IF(B8="","vendors_name wajib; ","")&IF(AND(H8<>"",COUNTIF(LOOKUPS!$A$2:$A$100,H8)=0),"status tidak valid; ","")&IF(AND(F8<>"",NOT(ISNUMBER(SEARCH("@",F8)))),"email tidak valid; ",""))
I9: =IF(AND(A9<>"",B9<>"",OR(H9="",COUNTIF(LOOKUPS!$A$2:$A$100,H9)>0),OR(F9="",ISNUMBER(SEARCH("@",F9)))),"","ERROR: "&IF(A9="","vendors_code wajib; ","")&IF(B9="","vendors_name wajib; ","")&IF(AND(H9<>"",COUNTIF(LOOKUPS!$A$2:$A$100,H9)=0),"status tidak valid; ","")&IF(AND(F9<>"",NOT(ISNUMBER(SEARCH("@",F9)))),"email tidak valid; ",""))
I10: =IF(AND(A10<>"",B10<>"",OR(H10="",COUNTIF(LOOKUPS!$A$2:$A$100,H10)>0),OR(F10="",ISNUMBER(SEARCH("@",F10)))),"","ERROR: "&IF(A10="","vendors_code wajib; ","")&IF(B10="","vendors_name wajib; ","")&IF(AND(H10<>"",COUNTIF(LOOKUPS!$A$2:$A$100,H10)=0),"status tidak valid; ","")&IF(AND(F10<>"",NOT(ISNUMBER(SEARCH("@",F10)))),"email tidak valid; ",""))
I11: =IF(AND(A11<>"",B11<>"",OR(H11="",COUNTIF(LOOKUPS!$A$2:$A$100,H11)>0),OR(F11="",ISNUMBER(SEARCH("@",F11)))),"","ERROR: "&IF(A11="","vendors_code wajib; ","")&IF(B11="","vendors_name wajib; ","")&IF(AND(H11<>"",COUNTIF(LOOKUPS!$A$2:$A$100,H11)=0),"status tidak valid; ","")&IF(AND(F11<>"",NOT(ISNUMBER(SEARCH("@",F11)))),"email tidak valid; ",""))
I12: =IF(AND(A12<>"",B12<>"",OR(H12="",COUNTIF(LOOKUPS!$A$2:$A$100,H12)>0),OR(F12="",ISNUMBER(SEARCH("@",F12)))),"","ERROR: "&IF(A12="","vendors_code wajib; ","")&IF(B12="","vendors_name wajib; ","")&IF(AND(H12<>"",COUNTIF(LOOKUPS!$A$2:$A$100,H12)=0),"status tidak valid; ","")&IF(AND(F12<>"",NOT(ISNUMBER(SEARCH("@",F12)))),"email tidak valid; ",""))
I13: =IF(AND(A13<>"",B13<>"",OR(H13="",COUNTIF(LOOKUPS!$A$2:$A$100,H13)>0),OR(F13="",ISNUMBER(SEARCH("@",F13)))),"","ERROR: "&IF(A13="","vendors_code wajib; ","")&IF(B13="","vendors_name wajib; ","")&IF(AND(H13<>"",COUNTIF(LOOKUPS!$A$2:$A$100,H13)=0),"status tidak valid; ","")&IF(AND(F13<>"",NOT(ISNUMBER(SEARCH("@",F13)))),"email tidak valid; ",""))
I14: =IF(AND(A14<>"",B14<>"",OR(H14="",COUNTIF(LOOKUPS!$A$2:$A$100,H14)>0),OR(F14="",ISNUMBER(SEARCH("@",F14)))),"","ERROR: "&IF(A14="","vendors_code wajib; ","")&IF(B14="","vendors_name wajib; ","")&IF(AND(H14<>"",COUNTIF(LOOKUPS!$A$2:$A$100,H14)=0),"status tidak valid; ","")&IF(AND(F14<>"",NOT(ISNUMBER(SEARCH("@",F14)))),"email tidak valid; ",""))
I15: =IF(AND(A15<>"",B15<>"",OR(H15="",COUNTIF(LOOKUPS!$A$2:$A$100,H15)>0),OR(F15="",ISNUMBER(SEARCH("@",F15)))),"","ERROR: "&IF(A15="","vendors_code wajib; ","")&IF(B15="","vendors_name wajib; ","")&IF(AND(H15<>"",COUNTIF(LOOKUPS!$A$2:$A$100,H15)=0),"status tidak valid; ","")&IF(AND(F15<>"",NOT(ISNUMBER(SEARCH("@",F15)))),"email tidak valid; ",""))
I16: =IF(AND(A16<>"",B16<>"",OR(H16="",COUNTIF(LOOKUPS!$A$2:$A$100,H16)>0),OR(F16="",ISNUMBER(SEARCH("@",F16)))),"","ERROR: "&IF(A16="","vendors_code wajib; ","")&IF(B16="","vendors_name wajib; ","")&IF(AND(H16<>"",COUNTIF(LOOKUPS!$A$2:$A$100,H16)=0),"status tidak valid; ","")&IF(AND(F16<>"",NOT(ISNUMBER(SEARCH("@",F16)))),"email tidak valid; ",""))
I17: =IF(AND(A17<>"",B17<>"",OR(H17="",COUNTIF(LOOKUPS!$A$2:$A$100,H17)>0),OR(F17="",ISNUMBER(SEARCH("@",F17)))),"","ERROR: "&IF(A17="","vendors_code wajib; ","")&IF(B17="","vendors_name wajib; ","")&IF(AND(H17<>"",COUNTIF(LOOKUPS!$A$2:$A$100,H17)=0),"status tidak valid; ","")&IF(AND(F17<>"",NOT(ISNUMBER(SEARCH("@",F17)))),"email tidak valid; ",""))
I18: =IF(AND(A18<>"",B18<>"",OR(H18="",COUNTIF(LOOKUPS!$A$2:$A$100,H18)>0),OR(F18="",ISNUMBER(SEARCH("@",F18)))),"","ERROR: "&IF(A18="","vendors_code wajib; ","")&IF(B18="","vendors_name wajib; ","")&IF(AND(H18<>"",COUNTIF(LOOKUPS!$A$2:$A$100,H18)=0),"status tidak valid; ","")&IF(AND(F18<>"",NOT(ISNUMBER(SEARCH("@",F18)))),"email tidak valid; ",""))
... I2000: =IF(AND(A2000<>"",B2000<>"",OR(H2000="",COUNTIF(LOOKUPS!$A$2:$A$100,H2000)>0),OR(F2000="",ISNUMBER(SEARCH("@",F2000)))),"","ERROR: "&IF(A2000="","vendors_code wajib; ","")&IF(B2000="","vendors_name wajib; ","")&IF(AND(H2000<>"",COUNTIF(LOOKUPS!$A$2:$A$100,H2000)=0),"status tidak valid; ","")&IF(AND(F2000<>"",NOT(ISNUMBER(SEARCH("@",F2000)))),"email tidak valid; ",""))

Sheet LOOKUPS
A1: status | B1: unit | C1: office_code | D1: tax_code | E1: source_note | F1: origin_type | G1: bank_currency | H1: dept_code | I1: level_type | J1: grade
A2: active | B2: PCS | C2: BGR | D2: NONPPN | E2: master_office.sql + master_tax.sql + fallback template units | F2: Local | G2: IDR | H2: MPR | I2: Manager | J2: A
A3: inactive | B3: BOX | C3: BKS | D3: PPN11 | E3: master_office.sql + master_tax.sql + fallback template units | F3: Import | G3: USD | H3: CRM | I3: Staff | J3: B
B4: UNIT | C4: TGR | E4: master_office.sql + master_tax.sql + fallback template units | G4: EUR | H4: WQS | J4: C
B5: CARTON | C5: BDG | E5: master_office.sql + master_tax.sql + fallback template units | G5: CNY | H5: SCM
B6: PAK | C6: SLO | E6: master_office.sql + master_tax.sql + fallback template units | H6: ACT
C7: SMG | E7: master_office.sql + master_tax.sql + fallback template units | H7: FIN
C8: KAL | E8: master_office.sql + master_tax.sql + fallback template units | H8: HRL
C9: JGY | E9: master_office.sql + master_tax.sql + fallback template units | H9: PQP
H10: ITC
H11: SYS

Sheet EXAMPLES
A1: entity | B1: type | C1: sample_row | D1: reason
A2: MASTER_PRODUCTS | B2: valid | C2: SKU010 | Produk X | BMHP | PCS | active | D2: Semua mandatory terisi, status valid
A3: MASTER_PRODUCTS | B3: invalid | C3: | Produk X | BMHP | PCS | active | D3: sku wajib, tidak boleh kosong
A4: MASTER_CUSTOMERS | B4: valid | C4: CUST010 | Customer X | RS | Hospital | Bogor | BGR | ... | active | D4: Code+name terisi, office_code pakai kode
A5: MASTER_CUSTOMERS | B5: invalid | C5: CUST010 | | RS | Hospital | Bogor | BGR | ... | D5: customers_name wajib
A6: MASTER_VENDORS | B6: valid | C6: VEND010 | PT Vendor X | Forwarding | Jakarta | ... | active | D6: Code+name terisi
A7: MASTER_VENDORS | B7: invalid | C7: vend010 | PT Vendor X | ... | D7: akan di-uppercase, tapi tetap disarankan kirim uppercase
A8: MASTER_MANUFACTURES | B8: valid | C8: MNF010 | Manufacture X | ... | origin_type=Import | bank_currency=USD | status=active | D8: Code+name wajib terisi, origin/currency/status valid
A9: MASTER_MANUFACTURES | B9: invalid | C9: MNF010 | | ... | D9: manufacture_name wajib
A10: MASTER_EMPLOYEES | B10: valid | C10: FIN240101 | Employee X | FIN | BGR | 2024 | 01 | Staff | A | ... | active | D10: Mandatory terisi + enum valid
A11: MASTER_EMPLOYEES | B11: invalid | C11: | Employee X | FIN | BGR | 2024 | 13 | Staff | Z | ... | D11: join_month harus 01-12 dan grade hanya A/B/C

Sheet VALIDATION_RULES
A1: entity | B1: column | C1: required | D1: rule | E1: error_prevention
A2: MASTER_PRODUCTS | B2: sku | C2: Y | D2: Tidak boleh kosong, max 50, unik | E2: Simpan sebagai Text, hindari duplikat
A3: MASTER_PRODUCTS | B3: products_name | C3: Y | D3: Tidak boleh kosong, max 200 | E3: Isi nama produk valid
A4: MASTER_PRODUCTS | B4: status | C4: N | D4: Gunakan active/inactive | E4: Pakai dropdown status
A5: MASTER_CUSTOMERS | B5: customers_code | C5: Y | D5: Tidak boleh kosong, max 50, unik | E5: Text format, no trailing spaces
A6: MASTER_CUSTOMERS | B6: customers_name | C6: Y | D6: Tidak boleh kosong, max 200 | E6: Wajib isi
A7: MASTER_CUSTOMERS | B7: office_code | C7: N | D7: Gunakan kode office | E7: Pilih dari lookup office
A8: MASTER_VENDORS | B8: vendors_code | C8: Y | D8: Tidak boleh kosong, max 50, unik | E8: Text format
A9: MASTER_VENDORS | B9: vendors_name | C9: Y | D9: Tidak boleh kosong, max 150 | E9: Wajib isi
A10: ALL | B10: CSV output | C10: Y | D10: UTF-8, comma delimiter | E10: Jangan ubah header
A11: MASTER_MANUFACTURES | B11: manufacture_code | C11: Y | D11: Tidak boleh kosong, max 50, unik | E11: Simpan text dan uppercase
A12: MASTER_MANUFACTURES | B12: manufacture_name | C12: Y | D12: Tidak boleh kosong, max 150 | E12: Wajib isi
... A23: MASTER_EMPLOYEES | B23: status | C23: N | D23: active/inactive (default active) | E23: Pakai dropdown

Sheet TEMPLATE_MASTER_MANUFACTURES
A1: manufacture_code | B1: manufacture_name | C1: brand_name | D1: origin_type | E1: country | F1: city | G1: address | H1: phone | I1: email | J1: pic_name | K1: pic_position | L1: pic_phone | M1: pic_email | N1: bank_name | O1: bank_account_name | P1: bank_account_number | Q1: bank_swift_code | R1: bank_iban | S1: bank_currency | T1: website | U1: status | V1: VALIDATION_ERROR
A2: MNF001 | B2: Manufacture Satu | C2: Brand Satu | D2: Import | E2: China | F2: Suzhou | G2: Alamat principal 1 | H2: 0215550001 | I2: mnf001@example.com | J2: Andi | K2: Sales Manager | L2: 081200000003 | M2: andi@example.com | N2: ABC Bank | O2: PT Manufacture Satu | P2: 1234567890 | Q2: ABCIDJA | R2: ID1234567890 | S2: IDR | T2: https://example.com | U2: active | V2: =IF(AND(A2<>"",B2<>"",OR(D2="",COUNTIF(LOOKUPS!$F$2:$F$100,D2)>0),OR(S2="",COUNTIF(LOOKUPS!$G$2:$G$100,S2)>0),OR(U2="",COUNTIF(LOOKUPS!$A$2:$A$100,U2)>0),OR(I2="",ISNUMBER(SEARCH("@",I2))),OR(M2="",ISNUMBER(SEARCH("@",M2)))),"","ERROR: "&IF(A2="","manufacture_code wajib; ","")&IF(B2="","manufacture_name wajib; ","")&IF(AND(D2<>"",COUNTIF(LOOKUPS!$F$2:$F$100,D2)=0),"origin_type tidak valid; ","")&IF(AND(S2<>"",COUNTIF(LOOKUPS!$G$2:$G$100,S2)=0),"bank_currency tidak valid; ","")&IF(AND(U2<>"",COUNTIF(LOOKUPS!$A$2:$A$100,U2)=0),"status tidak valid; ","")&IF(AND(I2<>"",NOT(ISNUMBER(SEARCH("@",I2)))),"email tidak valid; ","")&IF(AND(M2<>"",NOT(ISNUMBER(SEARCH("@",M2)))),"pic_email tidak valid; ",""))
A3: MNF002 | B3: Manufacture Dua | C3: Brand Dua | D3: Local | E3: Indonesia | F3: Bogor | G3: Alamat principal 2 | H3: 02515550002 | I3: mnf002@example.com | J3: Budi | K3: Director | L3: 081200000004 | M3: budi@example.com | N3: DEF Bank | O3: PT Manufacture Dua | P3: 2233445566 | R3: ID9988776655 | S3: IDR | T3: https://example.org | U3: active | V3: =IF(AND(A3<>"",B3<>"",OR(D3="",COUNTIF(LOOKUPS!$F$2:$F$100,D3)>0),OR(S3="",COUNTIF(LOOKUPS!$G$2:$G$100,S3)>0),OR(U3="",COUNTIF(LOOKUPS!$A$2:$A$100,U3)>0),OR(I3="",ISNUMBER(SEARCH("@",I3))),OR(M3="",ISNUMBER(SEARCH("@",M3)))),"","ERROR: "&IF(A3="","manufacture_code wajib; ","")&IF(B3="","manufacture_name wajib; ","")&IF(AND(D3<>"",COUNTIF(LOOKUPS!$F$2:$F$100,D3)=0),"origin_type tidak valid; ","")&IF(AND(S3<>"",COUNTIF(LOOKUPS!$G$2:$G$100,S3)=0),"bank_currency tidak valid; ","")&IF(AND(U3<>"",COUNTIF(LOOKUPS!$A$2:$A$100,U3)=0),"status tidak valid; ","")&IF(AND(I3<>"",NOT(ISNUMBER(SEARCH("@",I3)))),"email tidak valid; ","")&IF(AND(M3<>"",NOT(ISNUMBER(SEARCH("@",M3)))),"pic_email tidak valid; ",""))
A4: MNF003 | B4: Manufacture Tiga | C4: Brand Tiga | D4: Import | E4: Germany | F4: Berlin | G4: Alamat principal 3 | H4: 030123456 | I4: mnf003@example.com | J4: Citra | K4: Procurement Lead | L4: 081200000005 | M4: citra@example.com | N4: GHI Bank | O4: PT Manufacture Tiga | P4: 9988776655 | Q4: GHIIDEBB | R4: DE1122334455 | S4: EUR | T4: https://example.net | U4: inactive | V4: =IF(AND(A4<>"",B4<>"",OR(D4="",COUNTIF(LOOKUPS!$F$2:$F$100,D4)>0),OR(S4="",COUNTIF(LOOKUPS!$G$2:$G$100,S4)>0),OR(U4="",COUNTIF(LOOKUPS!$A$2:$A$100,U4)>0),OR(I4="",ISNUMBER(SEARCH("@",I4))),OR(M4="",ISNUMBER(SEARCH("@",M4)))),"","ERROR: "&IF(A4="","manufacture_code wajib; ","")&IF(B4="","manufacture_name wajib; ","")&IF(AND(D4<>"",COUNTIF(LOOKUPS!$F$2:$F$100,D4)=0),"origin_type tidak valid; ","")&IF(AND(S4<>"",COUNTIF(LOOKUPS!$G$2:$G$100,S4)=0),"bank_currency tidak valid; ","")&IF(AND(U4<>"",COUNTIF(LOOKUPS!$A$2:$A$100,U4)=0),"status tidak valid; ","")&IF(AND(I4<>"",NOT(ISNUMBER(SEARCH("@",I4)))),"email tidak valid; ","")&IF(AND(M4<>"",NOT(ISNUMBER(SEARCH("@",M4)))),"pic_email tidak valid; ",""))
A5: MNF004 | B5: Manufacture Empat | C5: Brand Empat | D5: Local | E5: Indonesia | F5: Bandung | G5: Alamat principal 4 | H5: 0227000001 | I5: mnf004@example.com | J5: Deni | K5: Manager | L5: 081200000006 | M5: deni@example.com | N5: JKL Bank | O5: PT Manufacture Empat | P5: 1122112211 | R5: ID1122334455 | S5: IDR | T5: https://example.id | U5: active | V5: =IF(AND(A5<>"",B5<>"",OR(D5="",COUNTIF(LOOKUPS!$F$2:$F$100,D5)>0),OR(S5="",COUNTIF(LOOKUPS!$G$2:$G$100,S5)>0),OR(U5="",COUNTIF(LOOKUPS!$A$2:$A$100,U5)>0),OR(I5="",ISNUMBER(SEARCH("@",I5))),OR(M5="",ISNUMBER(SEARCH("@",M5)))),"","ERROR: "&IF(A5="","manufacture_code wajib; ","")&IF(B5="","manufacture_name wajib; ","")&IF(AND(D5<>"",COUNTIF(LOOKUPS!$F$2:$F$100,D5)=0),"origin_type tidak valid; ","")&IF(AND(S5<>"",COUNTIF(LOOKUPS!$G$2:$G$100,S5)=0),"bank_currency tidak valid; ","")&IF(AND(U5<>"",COUNTIF(LOOKUPS!$A$2:$A$100,U5)=0),"status tidak valid; ","")&IF(AND(I5<>"",NOT(ISNUMBER(SEARCH("@",I5)))),"email tidak valid; ","")&IF(AND(M5<>"",NOT(ISNUMBER(SEARCH("@",M5)))),"pic_email tidak valid; ",""))
A6: MNF005 | B6: Manufacture Lima | C6: Brand Lima | D6: Import | E6: Japan | F6: Tokyo | G6: Alamat principal 5 | H6: 0317000002 | I6: mnf005@example.com | J6: Eka | K6: PIC | L6: 081200000007 | M6: eka@example.com | N6: MNO Bank | O6: PT Manufacture Lima | P6: 7766554433 | Q6: MNOJPJT | R6: JP6677889900 | S6: USD | T6: https://example.co | U6: inactive | V6: =IF(AND(A6<>"",B6<>"",OR(D6="",COUNTIF(LOOKUPS!$F$2:$F$100,D6)>0),OR(S6="",COUNTIF(LOOKUPS!$G$2:$G$100,S6)>0),OR(U6="",COUNTIF(LOOKUPS!$A$2:$A$100,U6)>0),OR(I6="",ISNUMBER(SEARCH("@",I6))),OR(M6="",ISNUMBER(SEARCH("@",M6)))),"","ERROR: "&IF(A6="","manufacture_code wajib; ","")&IF(B6="","manufacture_name wajib; ","")&IF(AND(D6<>"",COUNTIF(LOOKUPS!$F$2:$F$100,D6)=0),"origin_type tidak valid; ","")&IF(AND(S6<>"",COUNTIF(LOOKUPS!$G$2:$G$100,S6)=0),"bank_currency tidak valid; ","")&IF(AND(U6<>"",COUNTIF(LOOKUPS!$A$2:$A$100,U6)=0),"status tidak valid; ","")&IF(AND(I6<>"",NOT(ISNUMBER(SEARCH("@",I6)))),"email tidak valid; ","")&IF(AND(M6<>"",NOT(ISNUMBER(SEARCH("@",M6)))),"pic_email tidak valid; ",""))
V7: =IF(AND(A7<>"",B7<>"",OR(D7="",COUNTIF(LOOKUPS!$F$2:$F$100,D7)>0),OR(S7="",COUNTIF(LOOKUPS!$G$2:$G$100,S7)>0),OR(U7="",COUNTIF(LOOKUPS!$A$2:$A$100,U7)>0),OR(I7="",ISNUMBER(SEARCH("@",I7))),OR(M7="",ISNUMBER(SEARCH("@",M7)))),"","ERROR: "&IF(A7="","manufacture_code wajib; ","")&IF(B7="","manufacture_name wajib; ","")&IF(AND(D7<>"",COUNTIF(LOOKUPS!$F$2:$F$100,D7)=0),"origin_type tidak valid; ","")&IF(AND(S7<>"",COUNTIF(LOOKUPS!$G$2:$G$100,S7)=0),"bank_currency tidak valid; ","")&IF(AND(U7<>"",COUNTIF(LOOKUPS!$A$2:$A$100,U7)=0),"status tidak valid; ","")&IF(AND(I7<>"",NOT(ISNUMBER(SEARCH("@",I7)))),"email tidak valid; ","")&IF(AND(M7<>"",NOT(ISNUMBER(SEARCH("@",M7)))),"pic_email tidak valid; ",""))
V8: =IF(AND(A8<>"",B8<>"",OR(D8="",COUNTIF(LOOKUPS!$F$2:$F$100,D8)>0),OR(S8="",COUNTIF(LOOKUPS!$G$2:$G$100,S8)>0),OR(U8="",COUNTIF(LOOKUPS!$A$2:$A$100,U8)>0),OR(I8="",ISNUMBER(SEARCH("@",I8))),OR(M8="",ISNUMBER(SEARCH("@",M8)))),"","ERROR: "&IF(A8="","manufacture_code wajib; ","")&IF(B8="","manufacture_name wajib; ","")&IF(AND(D8<>"",COUNTIF(LOOKUPS!$F$2:$F$100,D8)=0),"origin_type tidak valid; ","")&IF(AND(S8<>"",COUNTIF(LOOKUPS!$G$2:$G$100,S8)=0),"bank_currency tidak valid; ","")&IF(AND(U8<>"",COUNTIF(LOOKUPS!$A$2:$A$100,U8)=0),"status tidak valid; ","")&IF(AND(I8<>"",NOT(ISNUMBER(SEARCH("@",I8)))),"email tidak valid; ","")&IF(AND(M8<>"",NOT(ISNUMBER(SEARCH("@",M8)))),"pic_email tidak valid; ",""))
V9: =IF(AND(A9<>"",B9<>"",OR(D9="",COUNTIF(LOOKUPS!$F$2:$F$100,D9)>0),OR(S9="",COUNTIF(LOOKUPS!$G$2:$G$100,S9)>0),OR(U9="",COUNTIF(LOOKUPS!$A$2:$A$100,U9)>0),OR(I9="",ISNUMBER(SEARCH("@",I9))),OR(M9="",ISNUMBER(SEARCH("@",M9)))),"","ERROR: "&IF(A9="","manufacture_code wajib; ","")&IF(B9="","manufacture_name wajib; ","")&IF(AND(D9<>"",COUNTIF(LOOKUPS!$F$2:$F$100,D9)=0),"origin_type tidak valid; ","")&IF(AND(S9<>"",COUNTIF(LOOKUPS!$G$2:$G$100,S9)=0),"bank_currency tidak valid; ","")&IF(AND(U9<>"",COUNTIF(LOOKUPS!$A$2:$A$100,U9)=0),"status tidak valid; ","")&IF(AND(I9<>"",NOT(ISNUMBER(SEARCH("@",I9)))),"email tidak valid; ","")&IF(AND(M9<>"",NOT(ISNUMBER(SEARCH("@",M9)))),"pic_email tidak valid; ",""))
V10: =IF(AND(A10<>"",B10<>"",OR(D10="",COUNTIF(LOOKUPS!$F$2:$F$100,D10)>0),OR(S10="",COUNTIF(LOOKUPS!$G$2:$G$100,S10)>0),OR(U10="",COUNTIF(LOOKUPS!$A$2:$A$100,U10)>0),OR(I10="",ISNUMBER(SEARCH("@",I10))),OR(M10="",ISNUMBER(SEARCH("@",M10)))),"","ERROR: "&IF(A10="","manufacture_code wajib; ","")&IF(B10="","manufacture_name wajib; ","")&IF(AND(D10<>"",COUNTIF(LOOKUPS!$F$2:$F$100,D10)=0),"origin_type tidak valid; ","")&IF(AND(S10<>"",COUNTIF(LOOKUPS!$G$2:$G$100,S10)=0),"bank_currency tidak valid; ","")&IF(AND(U10<>"",COUNTIF(LOOKUPS!$A$2:$A$100,U10)=0),"status tidak valid; ","")&IF(AND(I10<>"",NOT(ISNUMBER(SEARCH("@",I10)))),"email tidak valid; ","")&IF(AND(M10<>"",NOT(ISNUMBER(SEARCH("@",M10)))),"pic_email tidak valid; ",""))
V11: =IF(AND(A11<>"",B11<>"",OR(D11="",COUNTIF(LOOKUPS!$F$2:$F$100,D11)>0),OR(S11="",COUNTIF(LOOKUPS!$G$2:$G$100,S11)>0),OR(U11="",COUNTIF(LOOKUPS!$A$2:$A$100,U11)>0),OR(I11="",ISNUMBER(SEARCH("@",I11))),OR(M11="",ISNUMBER(SEARCH("@",M11)))),"","ERROR: "&IF(A11="","manufacture_code wajib; ","")&IF(B11="","manufacture_name wajib; ","")&IF(AND(D11<>"",COUNTIF(LOOKUPS!$F$2:$F$100,D11)=0),"origin_type tidak valid; ","")&IF(AND(S11<>"",COUNTIF(LOOKUPS!$G$2:$G$100,S11)=0),"bank_currency tidak valid; ","")&IF(AND(U11<>"",COUNTIF(LOOKUPS!$A$2:$A$100,U11)=0),"status tidak valid; ","")&IF(AND(I11<>"",NOT(ISNUMBER(SEARCH("@",I11)))),"email tidak valid; ","")&IF(AND(M11<>"",NOT(ISNUMBER(SEARCH("@",M11)))),"pic_email tidak valid; ",""))
V12: =IF(AND(A12<>"",B12<>"",OR(D12="",COUNTIF(LOOKUPS!$F$2:$F$100,D12)>0),OR(S12="",COUNTIF(LOOKUPS!$G$2:$G$100,S12)>0),OR(U12="",COUNTIF(LOOKUPS!$A$2:$A$100,U12)>0),OR(I12="",ISNUMBER(SEARCH("@",I12))),OR(M12="",ISNUMBER(SEARCH("@",M12)))),"","ERROR: "&IF(A12="","manufacture_code wajib; ","")&IF(B12="","manufacture_name wajib; ","")&IF(AND(D12<>"",COUNTIF(LOOKUPS!$F$2:$F$100,D12)=0),"origin_type tidak valid; ","")&IF(AND(S12<>"",COUNTIF(LOOKUPS!$G$2:$G$100,S12)=0),"bank_currency tidak valid; ","")&IF(AND(U12<>"",COUNTIF(LOOKUPS!$A$2:$A$100,U12)=0),"status tidak valid; ","")&IF(AND(I12<>"",NOT(ISNUMBER(SEARCH("@",I12)))),"email tidak valid; ","")&IF(AND(M12<>"",NOT(ISNUMBER(SEARCH("@",M12)))),"pic_email tidak valid; ",""))
V13: =IF(AND(A13<>"",B13<>"",OR(D13="",COUNTIF(LOOKUPS!$F$2:$F$100,D13)>0),OR(S13="",COUNTIF(LOOKUPS!$G$2:$G$100,S13)>0),OR(U13="",COUNTIF(LOOKUPS!$A$2:$A$100,U13)>0),OR(I13="",ISNUMBER(SEARCH("@",I13))),OR(M13="",ISNUMBER(SEARCH("@",M13)))),"","ERROR: "&IF(A13="","manufacture_code wajib; ","")&IF(B13="","manufacture_name wajib; ","")&IF(AND(D13<>"",COUNTIF(LOOKUPS!$F$2:$F$100,D13)=0),"origin_type tidak valid; ","")&IF(AND(S13<>"",COUNTIF(LOOKUPS!$G$2:$G$100,S13)=0),"bank_currency tidak valid; ","")&IF(AND(U13<>"",COUNTIF(LOOKUPS!$A$2:$A$100,U13)=0),"status tidak valid; ","")&IF(AND(I13<>"",NOT(ISNUMBER(SEARCH("@",I13)))),"email tidak valid; ","")&IF(AND(M13<>"",NOT(ISNUMBER(SEARCH("@",M13)))),"pic_email tidak valid; ",""))
V14: =IF(AND(A14<>"",B14<>"",OR(D14="",COUNTIF(LOOKUPS!$F$2:$F$100,D14)>0),OR(S14="",COUNTIF(LOOKUPS!$G$2:$G$100,S14)>0),OR(U14="",COUNTIF(LOOKUPS!$A$2:$A$100,U14)>0),OR(I14="",ISNUMBER(SEARCH("@",I14))),OR(M14="",ISNUMBER(SEARCH("@",M14)))),"","ERROR: "&IF(A14="","manufacture_code wajib; ","")&IF(B14="","manufacture_name wajib; ","")&IF(AND(D14<>"",COUNTIF(LOOKUPS!$F$2:$F$100,D14)=0),"origin_type tidak valid; ","")&IF(AND(S14<>"",COUNTIF(LOOKUPS!$G$2:$G$100,S14)=0),"bank_currency tidak valid; ","")&IF(AND(U14<>"",COUNTIF(LOOKUPS!$A$2:$A$100,U14)=0),"status tidak valid; ","")&IF(AND(I14<>"",NOT(ISNUMBER(SEARCH("@",I14)))),"email tidak valid; ","")&IF(AND(M14<>"",NOT(ISNUMBER(SEARCH("@",M14)))),"pic_email tidak valid; ",""))
V15: =IF(AND(A15<>"",B15<>"",OR(D15="",COUNTIF(LOOKUPS!$F$2:$F$100,D15)>0),OR(S15="",COUNTIF(LOOKUPS!$G$2:$G$100,S15)>0),OR(U15="",COUNTIF(LOOKUPS!$A$2:$A$100,U15)>0),OR(I15="",ISNUMBER(SEARCH("@",I15))),OR(M15="",ISNUMBER(SEARCH("@",M15)))),"","ERROR: "&IF(A15="","manufacture_code wajib; ","")&IF(B15="","manufacture_name wajib; ","")&IF(AND(D15<>"",COUNTIF(LOOKUPS!$F$2:$F$100,D15)=0),"origin_type tidak valid; ","")&IF(AND(S15<>"",COUNTIF(LOOKUPS!$G$2:$G$100,S15)=0),"bank_currency tidak valid; ","")&IF(AND(U15<>"",COUNTIF(LOOKUPS!$A$2:$A$100,U15)=0),"status tidak valid; ","")&IF(AND(I15<>"",NOT(ISNUMBER(SEARCH("@",I15)))),"email tidak valid; ","")&IF(AND(M15<>"",NOT(ISNUMBER(SEARCH("@",M15)))),"pic_email tidak valid; ",""))
V16: =IF(AND(A16<>"",B16<>"",OR(D16="",COUNTIF(LOOKUPS!$F$2:$F$100,D16)>0),OR(S16="",COUNTIF(LOOKUPS!$G$2:$G$100,S16)>0),OR(U16="",COUNTIF(LOOKUPS!$A$2:$A$100,U16)>0),OR(I16="",ISNUMBER(SEARCH("@",I16))),OR(M16="",ISNUMBER(SEARCH("@",M16)))),"","ERROR: "&IF(A16="","manufacture_code wajib; ","")&IF(B16="","manufacture_name wajib; ","")&IF(AND(D16<>"",COUNTIF(LOOKUPS!$F$2:$F$100,D16)=0),"origin_type tidak valid; ","")&IF(AND(S16<>"",COUNTIF(LOOKUPS!$G$2:$G$100,S16)=0),"bank_currency tidak valid; ","")&IF(AND(U16<>"",COUNTIF(LOOKUPS!$A$2:$A$100,U16)=0),"status tidak valid; ","")&IF(AND(I16<>"",NOT(ISNUMBER(SEARCH("@",I16)))),"email tidak valid; ","")&IF(AND(M16<>"",NOT(ISNUMBER(SEARCH("@",M16)))),"pic_email tidak valid; ",""))
V17: =IF(AND(A17<>"",B17<>"",OR(D17="",COUNTIF(LOOKUPS!$F$2:$F$100,D17)>0),OR(S17="",COUNTIF(LOOKUPS!$G$2:$G$100,S17)>0),OR(U17="",COUNTIF(LOOKUPS!$A$2:$A$100,U17)>0),OR(I17="",ISNUMBER(SEARCH("@",I17))),OR(M17="",ISNUMBER(SEARCH("@",M17)))),"","ERROR: "&IF(A17="","manufacture_code wajib; ","")&IF(B17="","manufacture_name wajib; ","")&IF(AND(D17<>"",COUNTIF(LOOKUPS!$F$2:$F$100,D17)=0),"origin_type tidak valid; ","")&IF(AND(S17<>"",COUNTIF(LOOKUPS!$G$2:$G$100,S17)=0),"bank_currency tidak valid; ","")&IF(AND(U17<>"",COUNTIF(LOOKUPS!$A$2:$A$100,U17)=0),"status tidak valid; ","")&IF(AND(I17<>"",NOT(ISNUMBER(SEARCH("@",I17)))),"email tidak valid; ","")&IF(AND(M17<>"",NOT(ISNUMBER(SEARCH("@",M17)))),"pic_email tidak valid; ",""))
V18: =IF(AND(A18<>"",B18<>"",OR(D18="",COUNTIF(LOOKUPS!$F$2:$F$100,D18)>0),OR(S18="",COUNTIF(LOOKUPS!$G$2:$G$100,S18)>0),OR(U18="",COUNTIF(LOOKUPS!$A$2:$A$100,U18)>0),OR(I18="",ISNUMBER(SEARCH("@",I18))),OR(M18="",ISNUMBER(SEARCH("@",M18)))),"","ERROR: "&IF(A18="","manufacture_code wajib; ","")&IF(B18="","manufacture_name wajib; ","")&IF(AND(D18<>"",COUNTIF(LOOKUPS!$F$2:$F$100,D18)=0),"origin_type tidak valid; ","")&IF(AND(S18<>"",COUNTIF(LOOKUPS!$G$2:$G$100,S18)=0),"bank_currency tidak valid; ","")&IF(AND(U18<>"",COUNTIF(LOOKUPS!$A$2:$A$100,U18)=0),"status tidak valid; ","")&IF(AND(I18<>"",NOT(ISNUMBER(SEARCH("@",I18)))),"email tidak valid; ","")&IF(AND(M18<>"",NOT(ISNUMBER(SEARCH("@",M18)))),"pic_email tidak valid; ",""))
... V2000: =IF(AND(A2000<>"",B2000<>"",OR(D2000="",COUNTIF(LOOKUPS!$F$2:$F$100,D2000)>0),OR(S2000="",COUNTIF(LOOKUPS!$G$2:$G$100,S2000)>0),OR(U2000="",COUNTIF(LOOKUPS!$A$2:$A$100,U2000)>0),OR(I2000="",ISNUMBER(SEARCH("@",I2000))),OR(M2000="",ISNUMBER(SEARCH("@",M2000)))),"","ERROR: "&IF(A2000="","manufacture_code wajib; ","")&IF(B2000="","manufacture_name wajib; ","")&IF(AND(D2000<>"",COUNTIF(LOOKUPS!$F$2:$F$100,D2000)=0),"origin_type tidak valid; ","")&IF(AND(S2000<>"",COUNTIF(LOOKUPS!$G$2:$G$100,S2000)=0),"bank_currency tidak valid; ","")&IF(AND(U2000<>"",COUNTIF(LOOKUPS!$A$2:$A$100,U2000)=0),"status tidak valid; ","")&IF(AND(I2000<>"",NOT(ISNUMBER(SEARCH("@",I2000)))),"email tidak valid; ","")&IF(AND(M2000<>"",NOT(ISNUMBER(SEARCH("@",M2000)))),"pic_email tidak valid; ",""))

Sheet TEMPLATE_MASTER_EMPLOYEES
A1: employee_code | B1: employee_name | C1: dept_code | D1: office_code | E1: join_year | F1: join_month | G1: level_type | H1: grade | I1: nik | J1: npwp | K1: bpjs_tk_no | L1: bpjs_kes_no | M1: education | N1: phone | O1: email | P1: status | Q1: note | R1: VALIDATION_ERROR
A2: FIN240101 | B2: Employee Satu | C2: FIN | D2: BGR | E2: 2024 | F2: 01 | G2: Staff | H2: A | I2: 3201010101010001 | J2: 12.345.678.9-123.000 | K2: 1234567890 | L2: 9876543210 | M2: S1 | N2: 081200000004 | O2: employee1@example.com | P2: active | Q2: Import awal karyawan | R2: =IF(AND(B2<>"",C2<>"",D2<>"",E2<>"",F2<>"",COUNTIF(LOOKUPS!$H$2:$H$100,C2)>0,COUNTIF(LOOKUPS!$C$2:$C$100,D2)>0,OR(G2="",COUNTIF(LOOKUPS!$I$2:$I$100,G2)>0),OR(H2="",COUNTIF(LOOKUPS!$J$2:$J$100,H2)>0),OR(P2="",COUNTIF(LOOKUPS!$A$2:$A$100,P2)>0),LEN(E2)=4,VALUE(F2)>=1,VALUE(F2)<=12,OR(O2="",ISNUMBER(SEARCH("@",O2))),OR(A2="",LEN(A2)<=50)),"","ERROR: "&IF(B2="","employee_name wajib; ","")&IF(C2="","dept_code wajib; ","")&IF(D2="","office_code wajib; ","")&IF(E2="","join_year wajib; ","")&IF(F2="","join_month wajib; ","")&IF(AND(C2<>"",COUNTIF(LOOKUPS!$H$2:$H$100,C2)=0),"dept_code tidak valid; ","")&IF(AND(D2<>"",COUNTIF(LOOKUPS!$C$2:$C$100,D2)=0),"office_code tidak valid; ","")&IF(AND(G2<>"",COUNTIF(LOOKUPS!$I$2:$I$100,G2)=0),"level_type tidak valid; ","")&IF(AND(H2<>"",COUNTIF(LOOKUPS!$J$2:$J$100,H2)=0),"grade tidak valid; ","")&IF(AND(P2<>"",COUNTIF(LOOKUPS!$A$2:$A$100,P2)=0),"status tidak valid; ","")&IF(AND(O2<>"",NOT(ISNUMBER(SEARCH("@",O2)))),"email tidak valid; ","")&IF(AND(E2<>"",LEN(E2)<>4),"join_year harus 4 digit; ","")&IF(AND(F2<>"",OR(VALUE(F2)<1,VALUE(F2)>12)),"join_month 01-12; ",""))
A3: SCM240202 | B3: Employee Dua | C3: SCM | D3: TGR | E3: 2024 | F3: 02 | G3: Manager | H3: B | I3: 3201010101010002 | J3: 22.345.678.9-123.000 | K3: 2234567890 | L3: 8876543210 | M3: S1 | N3: 081200000005 | O3: employee2@example.com | P3: active | Q3: Supervisor gudang | R3: =IF(AND(B3<>"",C3<>"",D3<>"",E3<>"",F3<>"",COUNTIF(LOOKUPS!$H$2:$H$100,C3)>0,COUNTIF(LOOKUPS!$C$2:$C$100,D3)>0,OR(G3="",COUNTIF(LOOKUPS!$I$2:$I$100,G3)>0),OR(H3="",COUNTIF(LOOKUPS!$J$2:$J$100,H3)>0),OR(P3="",COUNTIF(LOOKUPS!$A$2:$A$100,P3)>0),LEN(E3)=4,VALUE(F3)>=1,VALUE(F3)<=12,OR(O3="",ISNUMBER(SEARCH("@",O3))),OR(A3="",LEN(A3)<=50)),"","ERROR: "&IF(B3="","employee_name wajib; ","")&IF(C3="","dept_code wajib; ","")&IF(D3="","office_code wajib; ","")&IF(E3="","join_year wajib; ","")&IF(F3="","join_month wajib; ","")&IF(AND(C3<>"",COUNTIF(LOOKUPS!$H$2:$H$100,C3)=0),"dept_code tidak valid; ","")&IF(AND(D3<>"",COUNTIF(LOOKUPS!$C$2:$C$100,D3)=0),"office_code tidak valid; ","")&IF(AND(G3<>"",COUNTIF(LOOKUPS!$I$2:$I$100,G3)=0),"level_type tidak valid; ","")&IF(AND(H3<>"",COUNTIF(LOOKUPS!$J$2:$J$100,H3)=0),"grade tidak valid; ","")&IF(AND(P3<>"",COUNTIF(LOOKUPS!$A$2:$A$100,P3)=0),"status tidak valid; ","")&IF(AND(O3<>"",NOT(ISNUMBER(SEARCH("@",O3)))),"email tidak valid; ","")&IF(AND(E3<>"",LEN(E3)<>4),"join_year harus 4 digit; ","")&IF(AND(F3<>"",OR(VALUE(F3)<1,VALUE(F3)>12)),"join_month 01-12; ",""))
B4: Employee Tiga | C4: ITC | D4: BDG | E4: 2024 | F4: 03 | G4: Staff | H4: C | I4: 3201010101010003 | J4: 32.345.678.9-123.000 | K4: 3234567890 | L4: 7876543210 | M4: S1 | N4: 081200000006 | O4: employee3@example.com | P4: inactive | Q4: Kode kosong akan auto-generate | R4: =IF(AND(B4<>"",C4<>"",D4<>"",E4<>"",F4<>"",COUNTIF(LOOKUPS!$H$2:$H$100,C4)>0,COUNTIF(LOOKUPS!$C$2:$C$100,D4)>0,OR(G4="",COUNTIF(LOOKUPS!$I$2:$I$100,G4)>0),OR(H4="",COUNTIF(LOOKUPS!$J$2:$J$100,H4)>0),OR(P4="",COUNTIF(LOOKUPS!$A$2:$A$100,P4)>0),LEN(E4)=4,VALUE(F4)>=1,VALUE(F4)<=12,OR(O4="",ISNUMBER(SEARCH("@",O4))),OR(A4="",LEN(A4)<=50)),"","ERROR: "&IF(B4="","employee_name wajib; ","")&IF(C4="","dept_code wajib; ","")&IF(D4="","office_code wajib; ","")&IF(E4="","join_year wajib; ","")&IF(F4="","join_month wajib; ","")&IF(AND(C4<>"",COUNTIF(LOOKUPS!$H$2:$H$100,C4)=0),"dept_code tidak valid; ","")&IF(AND(D4<>"",COUNTIF(LOOKUPS!$C$2:$C$100,D4)=0),"office_code tidak valid; ","")&IF(AND(G4<>"",COUNTIF(LOOKUPS!$I$2:$I$100,G4)=0),"level_type tidak valid; ","")&IF(AND(H4<>"",COUNTIF(LOOKUPS!$J$2:$J$100,H4)=0),"grade tidak valid; ","")&IF(AND(P4<>"",COUNTIF(LOOKUPS!$A$2:$A$100,P4)=0),"status tidak valid; ","")&IF(AND(O4<>"",NOT(ISNUMBER(SEARCH("@",O4)))),"email tidak valid; ","")&IF(AND(E4<>"",LEN(E4)<>4),"join_year harus 4 digit; ","")&IF(AND(F4<>"",OR(VALUE(F4)<1,VALUE(F4)>12)),"join_month 01-12; ",""))
A5: HRL240404 | B5: Employee Empat | C5: HRL | D5: BKS | E5: 2024 | F5: 04 | G5: Staff | I5: 3201010101010004 | J5: 42.345.678.9-123.000 | K5: 4234567890 | L5: 6876543210 | M5: S2 | N5: 081200000007 | O5: employee4@example.com | P5: active | Q5: - | R5: =IF(AND(B5<>"",C5<>"",D5<>"",E5<>"",F5<>"",COUNTIF(LOOKUPS!$H$2:$H$100,C5)>0,COUNTIF(LOOKUPS!$C$2:$C$100,D5)>0,OR(G5="",COUNTIF(LOOKUPS!$I$2:$I$100,G5)>0),OR(H5="",COUNTIF(LOOKUPS!$J$2:$J$100,H5)>0),OR(P5="",COUNTIF(LOOKUPS!$A$2:$A$100,P5)>0),LEN(E5)=4,VALUE(F5)>=1,VALUE(F5)<=12,OR(O5="",ISNUMBER(SEARCH("@",O5))),OR(A5="",LEN(A5)<=50)),"","ERROR: "&IF(B5="","employee_name wajib; ","")&IF(C5="","dept_code wajib; ","")&IF(D5="","office_code wajib; ","")&IF(E5="","join_year wajib; ","")&IF(F5="","join_month wajib; ","")&IF(AND(C5<>"",COUNTIF(LOOKUPS!$H$2:$H$100,C5)=0),"dept_code tidak valid; ","")&IF(AND(D5<>"",COUNTIF(LOOKUPS!$C$2:$C$100,D5)=0),"office_code tidak valid; ","")&IF(AND(G5<>"",COUNTIF(LOOKUPS!$I$2:$I$100,G5)=0),"level_type tidak valid; ","")&IF(AND(H5<>"",COUNTIF(LOOKUPS!$J$2:$J$100,H5)=0),"grade tidak valid; ","")&IF(AND(P5<>"",COUNTIF(LOOKUPS!$A$2:$A$100,P5)=0),"status tidak valid; ","")&IF(AND(O5<>"",NOT(ISNUMBER(SEARCH("@",O5)))),"email tidak valid; ","")&IF(AND(E5<>"",LEN(E5)<>4),"join_year harus 4 digit; ","")&IF(AND(F5<>"",OR(VALUE(F5)<1,VALUE(F5)>12)),"join_month 01-12; ",""))
A6: ACT240505 | B6: Employee Lima | C6: ACT | D6: SMG | E6: 2024 | F6: 05 | G6: Manager | H6: A | I6: 3201010101010005 | J6: 52.345.678.9-123.000 | K6: 5234567890 | L6: 5876543210 | M6: S1 | N6: 081200000008 | O6: employee5@example.com | P6: inactive | Q6: - | R6: =IF(AND(B6<>"",C6<>"",D6<>"",E6<>"",F6<>"",COUNTIF(LOOKUPS!$H$2:$H$100,C6)>0,COUNTIF(LOOKUPS!$C$2:$C$100,D6)>0,OR(G6="",COUNTIF(LOOKUPS!$I$2:$I$100,G6)>0),OR(H6="",COUNTIF(LOOKUPS!$J$2:$J$100,H6)>0),OR(P6="",COUNTIF(LOOKUPS!$A$2:$A$100,P6)>0),LEN(E6)=4,VALUE(F6)>=1,VALUE(F6)<=12,OR(O6="",ISNUMBER(SEARCH("@",O6))),OR(A6="",LEN(A6)<=50)),"","ERROR: "&IF(B6="","employee_name wajib; ","")&IF(C6="","dept_code wajib; ","")&IF(D6="","office_code wajib; ","")&IF(E6="","join_year wajib; ","")&IF(F6="","join_month wajib; ","")&IF(AND(C6<>"",COUNTIF(LOOKUPS!$H$2:$H$100,C6)=0),"dept_code tidak valid; ","")&IF(AND(D6<>"",COUNTIF(LOOKUPS!$C$2:$C$100,D6)=0),"office_code tidak valid; ","")&IF(AND(G6<>"",COUNTIF(LOOKUPS!$I$2:$I$100,G6)=0),"level_type tidak valid; ","")&IF(AND(H6<>"",COUNTIF(LOOKUPS!$J$2:$J$100,H6)=0),"grade tidak valid; ","")&IF(AND(P6<>"",COUNTIF(LOOKUPS!$A$2:$A$100,P6)=0),"status tidak valid; ","")&IF(AND(O6<>"",NOT(ISNUMBER(SEARCH("@",O6)))),"email tidak valid; ","")&IF(AND(E6<>"",LEN(E6)<>4),"join_year harus 4 digit; ","")&IF(AND(F6<>"",OR(VALUE(F6)<1,VALUE(F6)>12)),"join_month 01-12; ",""))
R7: =IF(AND(B7<>"",C7<>"",D7<>"",E7<>"",F7<>"",COUNTIF(LOOKUPS!$H$2:$H$100,C7)>0,COUNTIF(LOOKUPS!$C$2:$C$100,D7)>0,OR(G7="",COUNTIF(LOOKUPS!$I$2:$I$100,G7)>0),OR(H7="",COUNTIF(LOOKUPS!$J$2:$J$100,H7)>0),OR(P7="",COUNTIF(LOOKUPS!$A$2:$A$100,P7)>0),LEN(E7)=4,VALUE(F7)>=1,VALUE(F7)<=12,OR(O7="",ISNUMBER(SEARCH("@",O7))),OR(A7="",LEN(A7)<=50)),"","ERROR: "&IF(B7="","employee_name wajib; ","")&IF(C7="","dept_code wajib; ","")&IF(D7="","office_code wajib; ","")&IF(E7="","join_year wajib; ","")&IF(F7="","join_month wajib; ","")&IF(AND(C7<>"",COUNTIF(LOOKUPS!$H$2:$H$100,C7)=0),"dept_code tidak valid; ","")&IF(AND(D7<>"",COUNTIF(LOOKUPS!$C$2:$C$100,D7)=0),"office_code tidak valid; ","")&IF(AND(G7<>"",COUNTIF(LOOKUPS!$I$2:$I$100,G7)=0),"level_type tidak valid; ","")&IF(AND(H7<>"",COUNTIF(LOOKUPS!$J$2:$J$100,H7)=0),"grade tidak valid; ","")&IF(AND(P7<>"",COUNTIF(LOOKUPS!$A$2:$A$100,P7)=0),"status tidak valid; ","")&IF(AND(O7<>"",NOT(ISNUMBER(SEARCH("@",O7)))),"email tidak valid; ","")&IF(AND(E7<>"",LEN(E7)<>4),"join_year harus 4 digit; ","")&IF(AND(F7<>"",OR(VALUE(F7)<1,VALUE(F7)>12)),"join_month 01-12; ",""))
R8: =IF(AND(B8<>"",C8<>"",D8<>"",E8<>"",F8<>"",COUNTIF(LOOKUPS!$H$2:$H$100,C8)>0,COUNTIF(LOOKUPS!$C$2:$C$100,D8)>0,OR(G8="",COUNTIF(LOOKUPS!$I$2:$I$100,G8)>0),OR(H8="",COUNTIF(LOOKUPS!$J$2:$J$100,H8)>0),OR(P8="",COUNTIF(LOOKUPS!$A$2:$A$100,P8)>0),LEN(E8)=4,VALUE(F8)>=1,VALUE(F8)<=12,OR(O8="",ISNUMBER(SEARCH("@",O8))),OR(A8="",LEN(A8)<=50)),"","ERROR: "&IF(B8="","employee_name wajib; ","")&IF(C8="","dept_code wajib; ","")&IF(D8="","office_code wajib; ","")&IF(E8="","join_year wajib; ","")&IF(F8="","join_month wajib; ","")&IF(AND(C8<>"",COUNTIF(LOOKUPS!$H$2:$H$100,C8)=0),"dept_code tidak valid; ","")&IF(AND(D8<>"",COUNTIF(LOOKUPS!$C$2:$C$100,D8)=0),"office_code tidak valid; ","")&IF(AND(G8<>"",COUNTIF(LOOKUPS!$I$2:$I$100,G8)=0),"level_type tidak valid; ","")&IF(AND(H8<>"",COUNTIF(LOOKUPS!$J$2:$J$100,H8)=0),"grade tidak valid; ","")&IF(AND(P8<>"",COUNTIF(LOOKUPS!$A$2:$A$100,P8)=0),"status tidak valid; ","")&IF(AND(O8<>"",NOT(ISNUMBER(SEARCH("@",O8)))),"email tidak valid; ","")&IF(AND(E8<>"",LEN(E8)<>4),"join_year harus 4 digit; ","")&IF(AND(F8<>"",OR(VALUE(F8)<1,VALUE(F8)>12)),"join_month 01-12; ",""))
R9: =IF(AND(B9<>"",C9<>"",D9<>"",E9<>"",F9<>"",COUNTIF(LOOKUPS!$H$2:$H$100,C9)>0,COUNTIF(LOOKUPS!$C$2:$C$100,D9)>0,OR(G9="",COUNTIF(LOOKUPS!$I$2:$I$100,G9)>0),OR(H9="",COUNTIF(LOOKUPS!$J$2:$J$100,H9)>0),OR(P9="",COUNTIF(LOOKUPS!$A$2:$A$100,P9)>0),LEN(E9)=4,VALUE(F9)>=1,VALUE(F9)<=12,OR(O9="",ISNUMBER(SEARCH("@",O9))),OR(A9="",LEN(A9)<=50)),"","ERROR: "&IF(B9="","employee_name wajib; ","")&IF(C9="","dept_code wajib; ","")&IF(D9="","office_code wajib; ","")&IF(E9="","join_year wajib; ","")&IF(F9="","join_month wajib; ","")&IF(AND(C9<>"",COUNTIF(LOOKUPS!$H$2:$H$100,C9)=0),"dept_code tidak valid; ","")&IF(AND(D9<>"",COUNTIF(LOOKUPS!$C$2:$C$100,D9)=0),"office_code tidak valid; ","")&IF(AND(G9<>"",COUNTIF(LOOKUPS!$I$2:$I$100,G9)=0),"level_type tidak valid; ","")&IF(AND(H9<>"",COUNTIF(LOOKUPS!$J$2:$J$100,H9)=0),"grade tidak valid; ","")&IF(AND(P9<>"",COUNTIF(LOOKUPS!$A$2:$A$100,P9)=0),"status tidak valid; ","")&IF(AND(O9<>"",NOT(ISNUMBER(SEARCH("@",O9)))),"email tidak valid; ","")&IF(AND(E9<>"",LEN(E9)<>4),"join_year harus 4 digit; ","")&IF(AND(F9<>"",OR(VALUE(F9)<1,VALUE(F9)>12)),"join_month 01-12; ",""))
R10: =IF(AND(B10<>"",C10<>"",D10<>"",E10<>"",F10<>"",COUNTIF(LOOKUPS!$H$2:$H$100,C10)>0,COUNTIF(LOOKUPS!$C$2:$C$100,D10)>0,OR(G10="",COUNTIF(LOOKUPS!$I$2:$I$100,G10)>0),OR(H10="",COUNTIF(LOOKUPS!$J$2:$J$100,H10)>0),OR(P10="",COUNTIF(LOOKUPS!$A$2:$A$100,P10)>0),LEN(E10)=4,VALUE(F10)>=1,VALUE(F10)<=12,OR(O10="",ISNUMBER(SEARCH("@",O10))),OR(A10="",LEN(A10)<=50)),"","ERROR: "&IF(B10="","employee_name wajib; ","")&IF(C10="","dept_code wajib; ","")&IF(D10="","office_code wajib; ","")&IF(E10="","join_year wajib; ","")&IF(F10="","join_month wajib; ","")&IF(AND(C10<>"",COUNTIF(LOOKUPS!$H$2:$H$100,C10)=0),"dept_code tidak valid; ","")&IF(AND(D10<>"",COUNTIF(LOOKUPS!$C$2:$C$100,D10)=0),"office_code tidak valid; ","")&IF(AND(G10<>"",COUNTIF(LOOKUPS!$I$2:$I$100,G10)=0),"level_type tidak valid; ","")&IF(AND(H10<>"",COUNTIF(LOOKUPS!$J$2:$J$100,H10)=0),"grade tidak valid; ","")&IF(AND(P10<>"",COUNTIF(LOOKUPS!$A$2:$A$100,P10)=0),"status tidak valid; ","")&IF(AND(O10<>"",NOT(ISNUMBER(SEARCH("@",O10)))),"email tidak valid; ","")&IF(AND(E10<>"",LEN(E10)<>4),"join_year harus 4 digit; ","")&IF(AND(F10<>"",OR(VALUE(F10)<1,VALUE(F10)>12)),"join_month 01-12; ",""))
R11: =IF(AND(B11<>"",C11<>"",D11<>"",E11<>"",F11<>"",COUNTIF(LOOKUPS!$H$2:$H$100,C11)>0,COUNTIF(LOOKUPS!$C$2:$C$100,D11)>0,OR(G11="",COUNTIF(LOOKUPS!$I$2:$I$100,G11)>0),OR(H11="",COUNTIF(LOOKUPS!$J$2:$J$100,H11)>0),OR(P11="",COUNTIF(LOOKUPS!$A$2:$A$100,P11)>0),LEN(E11)=4,VALUE(F11)>=1,VALUE(F11)<=12,OR(O11="",ISNUMBER(SEARCH("@",O11))),OR(A11="",LEN(A11)<=50)),"","ERROR: "&IF(B11="","employee_name wajib; ","")&IF(C11="","dept_code wajib; ","")&IF(D11="","office_code wajib; ","")&IF(E11="","join_year wajib; ","")&IF(F11="","join_month wajib; ","")&IF(AND(C11<>"",COUNTIF(LOOKUPS!$H$2:$H$100,C11)=0),"dept_code tidak valid; ","")&IF(AND(D11<>"",COUNTIF(LOOKUPS!$C$2:$C$100,D11)=0),"office_code tidak valid; ","")&IF(AND(G11<>"",COUNTIF(LOOKUPS!$I$2:$I$100,G11)=0),"level_type tidak valid; ","")&IF(AND(H11<>"",COUNTIF(LOOKUPS!$J$2:$J$100,H11)=0),"grade tidak valid; ","")&IF(AND(P11<>"",COUNTIF(LOOKUPS!$A$2:$A$100,P11)=0),"status tidak valid; ","")&IF(AND(O11<>"",NOT(ISNUMBER(SEARCH("@",O11)))),"email tidak valid; ","")&IF(AND(E11<>"",LEN(E11)<>4),"join_year harus 4 digit; ","")&IF(AND(F11<>"",OR(VALUE(F11)<1,VALUE(F11)>12)),"join_month 01-12; ",""))
R12: =IF(AND(B12<>"",C12<>"",D12<>"",E12<>"",F12<>"",COUNTIF(LOOKUPS!$H$2:$H$100,C12)>0,COUNTIF(LOOKUPS!$C$2:$C$100,D12)>0,OR(G12="",COUNTIF(LOOKUPS!$I$2:$I$100,G12)>0),OR(H12="",COUNTIF(LOOKUPS!$J$2:$J$100,H12)>0),OR(P12="",COUNTIF(LOOKUPS!$A$2:$A$100,P12)>0),LEN(E12)=4,VALUE(F12)>=1,VALUE(F12)<=12,OR(O12="",ISNUMBER(SEARCH("@",O12))),OR(A12="",LEN(A12)<=50)),"","ERROR: "&IF(B12="","employee_name wajib; ","")&IF(C12="","dept_code wajib; ","")&IF(D12="","office_code wajib; ","")&IF(E12="","join_year wajib; ","")&IF(F12="","join_month wajib; ","")&IF(AND(C12<>"",COUNTIF(LOOKUPS!$H$2:$H$100,C12)=0),"dept_code tidak valid; ","")&IF(AND(D12<>"",COUNTIF(LOOKUPS!$C$2:$C$100,D12)=0),"office_code tidak valid; ","")&IF(AND(G12<>"",COUNTIF(LOOKUPS!$I$2:$I$100,G12)=0),"level_type tidak valid; ","")&IF(AND(H12<>"",COUNTIF(LOOKUPS!$J$2:$J$100,H12)=0),"grade tidak valid; ","")&IF(AND(P12<>"",COUNTIF(LOOKUPS!$A$2:$A$100,P12)=0),"status tidak valid; ","")&IF(AND(O12<>"",NOT(ISNUMBER(SEARCH("@",O12)))),"email tidak valid; ","")&IF(AND(E12<>"",LEN(E12)<>4),"join_year harus 4 digit; ","")&IF(AND(F12<>"",OR(VALUE(F12)<1,VALUE(F12)>12)),"join_month 01-12; ",""))
R13: =IF(AND(B13<>"",C13<>"",D13<>"",E13<>"",F13<>"",COUNTIF(LOOKUPS!$H$2:$H$100,C13)>0,COUNTIF(LOOKUPS!$C$2:$C$100,D13)>0,OR(G13="",COUNTIF(LOOKUPS!$I$2:$I$100,G13)>0),OR(H13="",COUNTIF(LOOKUPS!$J$2:$J$100,H13)>0),OR(P13="",COUNTIF(LOOKUPS!$A$2:$A$100,P13)>0),LEN(E13)=4,VALUE(F13)>=1,VALUE(F13)<=12,OR(O13="",ISNUMBER(SEARCH("@",O13))),OR(A13="",LEN(A13)<=50)),"","ERROR: "&IF(B13="","employee_name wajib; ","")&IF(C13="","dept_code wajib; ","")&IF(D13="","office_code wajib; ","")&IF(E13="","join_year wajib; ","")&IF(F13="","join_month wajib; ","")&IF(AND(C13<>"",COUNTIF(LOOKUPS!$H$2:$H$100,C13)=0),"dept_code tidak valid; ","")&IF(AND(D13<>"",COUNTIF(LOOKUPS!$C$2:$C$100,D13)=0),"office_code tidak valid; ","")&IF(AND(G13<>"",COUNTIF(LOOKUPS!$I$2:$I$100,G13)=0),"level_type tidak valid; ","")&IF(AND(H13<>"",COUNTIF(LOOKUPS!$J$2:$J$100,H13)=0),"grade tidak valid; ","")&IF(AND(P13<>"",COUNTIF(LOOKUPS!$A$2:$A$100,P13)=0),"status tidak valid; ","")&IF(AND(O13<>"",NOT(ISNUMBER(SEARCH("@",O13)))),"email tidak valid; ","")&IF(AND(E13<>"",LEN(E13)<>4),"join_year harus 4 digit; ","")&IF(AND(F13<>"",OR(VALUE(F13)<1,VALUE(F13)>12)),"join_month 01-12; ",""))
