Workbook

Sheet 1_Manufactures
A1: ✅ Data hijau = sudah ada di sistem (akan di-skip saat upload). Tambahkan principal baru di bawah baris biru.
A2: manufacture_code | B2: manufacture_name | C2: brand_name | D2: origin_type | E2: country | F2: city | G2: address | H2: phone | I2: email | J2: status
A3: Kode unik principal *WAJIB* | B3: Nama lengkap principal *WAJIB* | C3: Nama brand/merek dagang | D3: Local / Import | E3: Negara asal | F3: Kota | G3: Alamat lengkap | H3: No. telepon | I3: Alamat email | J3: active / inactive
A4: YAXIN | B4: Suzhou Yaxin Medical Products Co., Ltd | C4: RIZKIMED | D4: Import | E4: China | F4: Suzhou | G4: No.12, Zhongta Road, Mudu Town, Suzhou 215101, Jiangsu province, China | H4: +86 152 5017 8777 | I4: yaxin@yx-yiliao.com | J4: active
A5: NANCHANG | B5: Nanchang Kanghua Health Materials Co., Ltd | C5: RIZKIMED | D5: Import | E5: China | F5: Jianxian Nanchang | G5: Moonlight Road Medical Device Technology Park, Jinxian Nanchang 331700 Jiangxi China | H5: +86 153 9791 1825 | I5: sales6@jxkh.cn | J5: active
A6: CATHAY | B6: CATHAY MANUFACTURING CORP | C6: CATHAY | D6: Import | E6: China | F6: Shanghai | G6: Room 1510, No. 20, Lane 699 Guang Fu Lin Road, Songjiang District, Shanghai, China | H6: +86 138 1688 9961 | I6: jenny.feng@cathaymanufacturing.com | J6: active
A7: EXCELLENTCARE | B7: EXCELLENTCARE MEDICAL (HUIZHOU) LTD | C7: RIZKIMED | D7: Import | E7: China | F7: Huizhou | G7: Shatou Industrial Zone, Yuanzhou Town, Boluo Country, Huizhou, 516123, Guangdong, China | H7: 0752-6358333-302 | I7: info@excellentcare.com.cn | J7: active
A8: CELECARE | B8: WENZHOU CELECARE MEDICAL INSTRUMENTS CO., LTD | C8: RIZKIMED | D8: Import | E8: China | F8: Wenzhou | G8: NO.407 XIAJIN RD(1-4th Floor), JINZHU INDUSTRIAL ZONE, NANBAIXIANG STREET, OUHAI DISTRICT, WENZHOU, ZHEJIANG, CHINA | H8: +86-577-56708225 | I8: info@celecare.com | J8: active
A9: MEDPLUS | B9: MEDPLUS INC | C9: MEDPLUS | D9: Import | E9: China | F9: GUANGZHOU | G9: 4TH FLOOR, BUILDING6, NO. 586 ZHONGSHUN ROAD, ZHONGCUN, PANYU DISTRICT, GUANGZHOU, 511495, CHINA | H9: +86 20 3477 3301 | I9: info@gzmedplus.com | J9: active
A10: ⬇ Tambahkan principal baru di baris berikutnya

Sheet 2_Vendors
A1: ✅ Data hijau = sudah ada di sistem. Tambahkan vendor baru di bawah baris biru.
A2: vendors_code | B2: vendors_name | C2: vendor_type | D2: category | E2: city | F2: phone | G2: email | H2: npwp | I2: status
A3: Kode unik vendor *WAJIB* | B3: Nama vendor *WAJIB* | C3: Forwarding / Logistic / Lainnya | D3: Dept: SCM,ACT,FIN,dll | E3: Kota vendor | F3: No. telepon | G3: Alamat email | H3: NPWP (format: 01.234.567.8-999.000) | I3: active / inactive
A4: FOR001 | B4: PT NOATUM LOGISTIC INDONESIA | C4: Forwarding | D4: SCM | E4: JAKARTA PUSAT | F4: 021-57941901 | G4: ricky.kurniawan@noatumlogistics.com | H4: 0018045336017000 | I4: active
A5: FOR003 | B5: PT MATS INTERNASIONAL INDONESIA | C5: Forwarding | D5: SCM | E5: JAKARTA PUSAT | F5: 021-39837188 | G5: heri@mii.id | H5: 0317560167003000 | I5: active
A6: FOR004 | B6: PT ZEIST GLOBAL SERVICE | C6: Forwarding | D6: SCM | E6: JAKARTA UTARA | F6: 021-22455468 | G6: sales02@zeist.co.id | H6: 0536721616043000 | I6: active
A7: FOR005 | B7: PT GLOBAL LINK EXPRESS | C7: Forwarding | D7: SCM | E7: JAKARTA BARAT | F7: 021-21695069 | G7: pt.globallinkexpress@gmail.com | I7: active
A8: FOR009 | B8: PT GEN LOGISTIK INDONESIA | C8: Forwarding | D8: SCM | E8: Jakarta Selatan | F8: 081289943020 | G8: fajar@genlog.co.id | H8: 0824179485017000 | I8: active
A9: VEN003 | B9: PT EMIRAD INTERNATIONAL LOGISTICS | C9: Lainnya | D9: SCM | E9: Depok | F9: 081904092805 | G9: mktg.assoc@emiradlogistics.co.id | H9: 0025683335015000 | I9: active
A10: VEN004 | B10: PT AKBAR PUTRA MANDIRI LOGISTICS | C10: Lainnya | D10: SCM | E10: Bogor | F10: 085718293144 | G10: rudianto@apmlogistics.id | H10: 0015216260201000 | I10: active
A11: VEN005 | B11: PT MERPATI ALAM SEMESTA KARGO | C11: Lainnya | D11: SCM | E11: Bogor | F11: 081317147644 | G11: reza@mas-kargo.co.id | H11: 0019968734015000 | I11: active
A12: VEN006 | B12: BARAKA EXPRESS (Bogor) | C12: Lainnya | D12: SCM | E12: Bogor | F12: 085770537397 | G12: customercare@baraka-express.com | I12: active
A13: VEN007 | B13: BARAKA EXPRESS (Semarang) | C13: Lainnya | D13: SCM | E13: Semarang | F13: 0895383162130 | G13: customercare@baraka-express.com | I13: active
A14: VEN008 | B14: BARAKA EXPRESS (Solo) | C14: Lainnya | D14: SCM | E14: Solo | F14: 089699114771 | G14: customercare@baraka-express.com | I14: active
A15: VEN009 | B15: J&T CARGO | C15: Lainnya | D15: SCM | E15: Bogor | F15: 081287044235 | G15: jntcargocibinong@gmail.com | I15: active
A16: VEN010 | B16: LION PARCEL | C16: Lainnya | D16: SCM | E16: Bogor | F16: 081287044235 | I16: active
A17: ⬇ Tambahkan vendor baru di baris berikutnya

Sheet 3_Customers
A1: ✅ Data hijau = sudah ada di sistem (skip saat upload). Tambahkan customer baru di bawah baris biru. Total: 60 customer.
A2: customers_code | B2: customers_name | C2: category | D2: segment | E2: city | F2: office_code | G2: address | H2: phone | I2: email | J2: npwp | K2: status | L2: office_name
A3: Kode unik customer *WAJIB* | B3: Nama customer *WAJIB* | C3: RS Swasta / RS Pemerintah / Internal | D3: Hermina / Non Hermina / RSUD / Kantor | E3: Kota customer | F3: Kode office ← pilih dari dropdown | G3: Alamat lengkap | H3: No. telepon / WA | I3: Alamat email | J3: NPWP (format: 01.234.567.8-999.000) | K3: active / inactive | L3: Nama kantor — otomatis dari office_code 🔒
A4: BGR-INT | B4: Kantor Rizqullah Mediska Indonesia (Internal) | C4: Internal | D4: Kantor | F4: BGR | K4: active | L4: =IF(F4="","",IFERROR(INDEX('8_Office'!$B$3:$B$15,MATCH(F4,'8_Office'!$A$3:$A$15,0)),"⚠ Kode tidak ditemukan")) -> Rizqullah Mediska Indonesia
A5: BDG-INT | B5: Kantor Rizqullah Mediska Indonesia Bandung (Internal) | C5: Internal | D5: Kantor | F5: BDG | K5: active | L5: =IF(F5="","",IFERROR(INDEX('8_Office'!$B$3:$B$15,MATCH(F5,'8_Office'!$A$3:$A$15,0)),"⚠ Kode tidak ditemukan")) -> Rizqullah Mediska Indonesia Bandung
A6: BKS-INT | B6: Kantor Rizqullah Mediska Indonesia Bekasi (Internal) | C6: Internal | D6: Kantor | F6: BKS | K6: active | L6: =IF(F6="","",IFERROR(INDEX('8_Office'!$B$3:$B$15,MATCH(F6,'8_Office'!$A$3:$A$15,0)),"⚠ Kode tidak ditemukan")) -> Rizqullah Mediska Indonesia Bekasi
A7: TGR-INT | B7: Kantor Rizqullah Mediska Indonesia Tangerang (Internal) | C7: Internal | D7: Kantor | F7: TGR | K7: active | L7: =IF(F7="","",IFERROR(INDEX('8_Office'!$B$3:$B$15,MATCH(F7,'8_Office'!$A$3:$A$15,0)),"⚠ Kode tidak ditemukan")) -> Rizqullah Mediska Indonesia Tangerang
A8: SLO-INT | B8: Kantor Rizqullah Mediska Indonesia Jawa Tengah (Solo) (Internal) | C8: Internal | D8: Kantor | F8: SLO | K8: active | L8: =IF(F8="","",IFERROR(INDEX('8_Office'!$B$3:$B$15,MATCH(F8,'8_Office'!$A$3:$A$15,0)),"⚠ Kode tidak ditemukan")) -> Rizqullah Mediska Indonesia Jawa Tengah (Solo)
A9: SMG-INT | B9: Kantor Rizqullah Mediska Indonesia Semarang (Internal) | C9: Internal | D9: Kantor | F9: SMG | K9: active | L9: =IF(F9="","",IFERROR(INDEX('8_Office'!$B$3:$B$15,MATCH(F9,'8_Office'!$A$3:$A$15,0)),"⚠ Kode tidak ditemukan")) -> Rizqullah Mediska Indonesia Semarang
A10: JGY-INT | B10: Kantor Depo Yogyakarta (Internal) | C10: Internal | D10: Kantor | F10: JGY | K10: active | L10: =IF(F10="","",IFERROR(INDEX('8_Office'!$B$3:$B$15,MATCH(F10,'8_Office'!$A$3:$A$15,0)),"⚠ Kode tidak ditemukan")) -> Depo Yogyakarta
A11: KAL-INT | B11: Kantor Depo Kalimantan (Internal) | C11: Internal | D11: Kantor | F11: KAL | K11: active | L11: =IF(F11="","",IFERROR(INDEX('8_Office'!$B$3:$B$15,MATCH(F11,'8_Office'!$A$3:$A$15,0)),"⚠ Kode tidak ditemukan")) -> Depo Kalimantan
A12: SYS-INT | B12: Kantor SYS (Internal) | C12: Internal | D12: Kantor | F12: SYS | K12: active | L12: =IF(F12="","",IFERROR(INDEX('8_Office'!$B$3:$B$15,MATCH(F12,'8_Office'!$A$3:$A$15,0)),"⚠ Kode tidak ditemukan")) -> SYS
A13: H001 | B13: RS HERMINA ACEH | C13: RS Swasta | D13: Hermina | E13: Kab Aceh Besar | F13: BGR | G13: Jl.Soekarno Hatta RT 000 RW 000, Aje Cut Ingin Jaya Kab Aceh Besar Aceh | H13: 06518072525 | J13: 42.455.114.1.108.000 | K13: active | L13: =IF(F13="","",IFERROR(INDEX('8_Office'!$B$3:$B$15,MATCH(F13,'8_Office'!$A$3:$A$15,0)),"⚠ Kode tidak ditemukan")) -> Rizqullah Mediska Indonesia
A14: H002 | B14: RS HERMINA ARCAMANIK | C14: RS Swasta | D14: Hermina | E14: Kota Bandung | F14: BGR | G14: Jl. A.H. Nasution KM7 No. 50, Kel. Antapani Wetan, Kec. Antapani, kota Bandung | H14: 02287242525 | I14: farmasi.herminaarca@gmail.com | J14: 02.789.562.2.429-000 | K14: active | L14: =IF(F14="","",IFERROR(INDEX('8_Office'!$B$3:$B$15,MATCH(F14,'8_Office'!$A$3:$A$15,0)),"⚠ Kode tidak ditemukan")) -> Rizqullah Mediska Indonesia
A15: H003 | B15: RS HERMINA BALIKPAPAN | C15: RS Swasta | D15: Hermina | E15: Kota Balikpapan | F15: BGR | G15: Jl. MT Haryono RT 45, Sepingan Baru Balikpapan, Kalimantan Timur, Indonesia | H15: 05428515230 | I15: farmasi.balikpapan@herminahospitals.com | J15: 74.937.119.1.721.000 | K15: active | L15: =IF(F15="","",IFERROR(INDEX('8_Office'!$B$3:$B$15,MATCH(F15,'8_Office'!$A$3:$A$15,0)),"⚠ Kode tidak ditemukan")) -> Rizqullah Mediska Indonesia
A16: H004 | B16: RS HERMINA BANYUMANIK | C16: RS Swasta | D16: Hermina | E16: Kota Semarang | F16: SMG | G16: Jl. Jenderal Pol Anton Sujarwo No.195A, Srondol Wetan, Banyumanik, Kota Semarang, 50263 | H16: 02476488989 | I16: farmasi.banyumanik@gmail.com | J16: 31.720.421.2-517.000 | K16: active | L16: =IF(F16="","",IFERROR(INDEX('8_Office'!$B$3:$B$15,MATCH(F16,'8_Office'!$A$3:$A$15,0)),"⚠ Kode tidak ditemukan")) -> Rizqullah Mediska Indonesia Semarang
A17: H005 | B17: RS HERMINA BEKASI | C17: RS Swasta | D17: Hermina | E17: Kota Bekasi | F17: BKS | G17: Jl. Kemakmuran No.39, RT.004/RW.003, Marga Jaya, Kec. Bekasi Sel., Kota Bks, 17141 | H17: 0218842121 | I17: pengadaanfarmasi.rshbks@gmail.com | J17: 01.783.421.9-007.000 | K17: active | L17: =IF(F17="","",IFERROR(INDEX('8_Office'!$B$3:$B$15,MATCH(F17,'8_Office'!$A$3:$A$15,0)),"⚠ Kode tidak ditemukan")) -> Rizqullah Mediska Indonesia Bekasi
A18: H006 | B18: RS HERMINA BITUNG | C18: RS Swasta | D18: Hermina | E18: Kabupaten Tangerang | F18: TGR | G18: Jl. Raya Serang No.10, Kadu, Kec. Curug, Kabupaten Tangerang, Banten 15810 | H18: 02159497525 | J18: 73.379.780.7-451.000 | K18: active | L18: =IF(F18="","",IFERROR(INDEX('8_Office'!$B$3:$B$15,MATCH(F18,'8_Office'!$A$3:$A$15,0)),"⚠ Kode tidak ditemukan")) -> Rizqullah Mediska Indonesia Tangerang
A19: H007 | B19: RS HERMINA BOGOR | C19: RS Swasta | D19: Hermina | E19: Kota Bogor | F19: BGR | G19: Jalan Ring Road I Kav. 23, 25, 27, Curugmekar, Kec. Bogor Bar., Kota Bogor, 16113 | H19: 02518382525 | J19: 02.073.142.8.404.001 | K19: active | L19: =IF(F19="","",IFERROR(INDEX('8_Office'!$B$3:$B$15,MATCH(F19,'8_Office'!$A$3:$A$15,0)),"⚠ Kode tidak ditemukan")) -> Rizqullah Mediska Indonesia
A20: H008 | B20: RS HERMINA CIAWI | C20: RS Swasta | D20: Hermina | E20: Kabupaten Bogor | F20: BGR | G20: Jl. Raya Puncak - Gadog No.23, Pandansari, Kec. Ciawi, Kabupaten Bogor, 16720 | H20: 02518407575 | I20: ifrsciawi@gmail.com | J20: 08.614.217.1-743.4.000 | K20: active | L20: =IF(F20="","",IFERROR(INDEX('8_Office'!$B$3:$B$15,MATCH(F20,'8_Office'!$A$3:$A$15,0)),"⚠ Kode tidak ditemukan")) -> Rizqullah Mediska Indonesia
A21: H009 | B21: RS HERMINA CILEDUG | C21: RS Swasta | D21: Hermina | E21: Kota Tangerang | F21: TGR | G21: Jl. Cipto Mangunkusumo Gg. H. Mencong No. 3, Ciledug, Tangerang, Banten 15151 | H21: 02173454951 | I21: farmasiciledug@gmail.com | J21: 04.124.281.0.441.6000 | K21: active | L21: =IF(F21="","",IFERROR(INDEX('8_Office'!$B$3:$B$15,MATCH(F21,'8_Office'!$A$3:$A$15,0)),"⚠ Kode tidak ditemukan")) -> Rizqullah Mediska Indonesia Tangerang
A22: H010 | B22: RS HERMINA CILEGON | C22: RS Swasta | D22: Hermina | E22: Kota Cilegon | F22: TGR | G22: Kawasan PT Bonauli Real Estate, Jl. Bonakarta, Masigit, Kec. Jombang, Kota Cilegon, 42414 | H22: 02547812525 | I22: farmasi.herminacilegon@gmail.com | J22: 86.126.303.6-417.000 | K22: active | L22: =IF(F22="","",IFERROR(INDEX('8_Office'!$B$3:$B$15,MATCH(F22,'8_Office'!$A$3:$A$15,0)),"⚠ Kode tidak ditemukan")) -> Rizqullah Mediska Indonesia Tangerang
A23: H011 | B23: RS HERMINA CIPUTAT | C23: RS Swasta | D23: Hermina | E23: Kota Tangerang Selatan | F23: TGR | G23: Jl. Ciputat Raya Jl. Kertamukti No.2, Ciputat, Tangerang Selatan, Banten 15419 | H23: 02174702525 | I23: farmasi.ciputat@herminahospitals.com | J23: 31.190.968.3-411.000 | K23: active | L23: =IF(F23="","",IFERROR(INDEX('8_Office'!$B$3:$B$15,MATCH(F23,'8_Office'!$A$3:$A$15,0)),"⚠ Kode tidak ditemukan")) -> Rizqullah Mediska Indonesia Tangerang
A24: H012 | B24: RS HERMINA CIRUAS | C24: RS Swasta | D24: Hermina | E24: Kabupaten Serang | F24: TGR | G24: Jl. Raya Serang - Jkt No.Km.9, Ranjeng, Kec. Ciruas, Kabupaten Serang, Banten 42182 | H24: 0254281829 | I24: farmasi.ciruas@herminahospitals.com | J24: 70.970.383.9-401.000 | K24: active | L24: =IF(F24="","",IFERROR(INDEX('8_Office'!$B$3:$B$15,MATCH(F24,'8_Office'!$A$3:$A$15,0)),"⚠ Kode tidak ditemukan")) -> Rizqullah Mediska Indonesia Tangerang
A25: H013 | B25: RS HERMINA DAAN MOGOT | C25: RS Swasta | D25: Hermina | E25: Jakarta Barat | F25: TGR | G25: Jl. Kintamani Raya No.2, Kalideres, Kec. Kalideres, Kota Jakarta Barat 11840 | H25: 0215408989 | I25: farmasi.daanmogot@gmail.com | J25: 02.073.114.7-038.000 | K25: active | L25: =IF(F25="","",IFERROR(INDEX('8_Office'!$B$3:$B$15,MATCH(F25,'8_Office'!$A$3:$A$15,0)),"⚠ Kode tidak ditemukan")) -> Rizqullah Mediska Indonesia Tangerang
A26: H014 | B26: RS HERMINA DEPOK | C26: RS Swasta | D26: Hermina | E26: Kota Depok | F26: BGR | G26: Jl. Siliwangi No.50, Depok, Kec. Pancoran Mas, Kota Depok, Jawa Barat 16431 | H26: 0211500488 | J26: 01.973.467.2.007.000 | K26: active | L26: =IF(F26="","",IFERROR(INDEX('8_Office'!$B$3:$B$15,MATCH(F26,'8_Office'!$A$3:$A$15,0)),"⚠ Kode tidak ditemukan")) -> Rizqullah Mediska Indonesia
A27: H015 | B27: RS HERMINA GALAXY | C27: RS Swasta | D27: Hermina | E27: Kabupaten Bekasi | F27: BKS | G27: Ruko Grand Galaxy City, Jl. Boulevar Raya Bar., Jaka Setia, Kec. Bekasi Sel., 17147 | H27: 0218222525 | I27: farmasi.galaxy@herminahospitals.com | J27: 31.173.812.4-432.000 | K27: active | L27: =IF(F27="","",IFERROR(INDEX('8_Office'!$B$3:$B$15,MATCH(F27,'8_Office'!$A$3:$A$15,0)),"⚠ Kode tidak ditemukan")) -> Rizqullah Mediska Indonesia Bekasi
A28: H016 | B28: RS HERMINA GRAND WISATA | C28: RS Swasta | D28: Hermina | E28: Kabupaten Bekasi | F28: BKS | G28: Jl. West Gateway Blvd No.1 Blok JA 1, Lambangsari, Tambun Sel., Kabupaten Bekasi 17510 | H28: 02182651212 | J28: 21.026.393.5-431.000 | K28: active | L28: =IF(F28="","",IFERROR(INDEX('8_Office'!$B$3:$B$15,MATCH(F28,'8_Office'!$A$3:$A$15,0)),"⚠ Kode tidak ditemukan")) -> Rizqullah Mediska Indonesia Bekasi
A29: H017 | B29: RS HERMINA NUSANTARA | C29: RS Swasta | D29: Hermina | E29: Kabupaten Penajam Paser Utara | F29: BGR | G29: Kawasan Inti Pusat Pemerintahan, Bumi Harapan, Kec. Sepaku, Kab. Penajam Paser Utara, Kaltim | H29: 05428252520 | I29: farmasi.rsuherminanusantara@gmail.com | J29: 00.192.011.5.100.7.000 | K29: active | L29: =IF(F29="","",IFERROR(INDEX('8_Office'!$B$3:$B$15,MATCH(F29,'8_Office'!$A$3:$A$15,0)),"⚠ Kode tidak ditemukan")) -> Rizqullah Mediska Indonesia
A30: H018 | B30: RS HERMINA JATINEGARA | C30: RS Swasta | D30: Hermina | E30: Jakarta Timur | F30: BGR | G30: Jl. Jatinegara Barat 126 Jakarta Timur, DKI Jakarta 13320 | H30: 0218513838 | I30: farmasi.jatinegara@herminahospitals.com | J30: 01.920.115.1.007.000 | K30: active | L30: =IF(F30="","",IFERROR(INDEX('8_Office'!$B$3:$B$15,MATCH(F30,'8_Office'!$A$3:$A$15,0)),"⚠ Kode tidak ditemukan")) -> Rizqullah Mediska Indonesia
A31: H019 | B31: RS HERMINA KARAWANG | C31: RS Swasta | D31: Hermina | E31: Kabupaten Karawang | F31: BKS | G31: Jalan Tuparev, Blok Gg. Sukasari No.386A, Karawang Wetan, Kec. Karawang Tim., 41314 | H31: 02678412525 | I31: farmasi.karawang@herminahospitals.com | J31: 83.675.630.4-408.000 | K31: active | L31: =IF(F31="","",IFERROR(INDEX('8_Office'!$B$3:$B$15,MATCH(F31,'8_Office'!$A$3:$A$15,0)),"⚠ Kode tidak ditemukan")) -> Rizqullah Mediska Indonesia Bekasi
A32: H020 | B32: RS HERMINA KEMAYORAN | C32: RS Swasta | D32: Hermina | E32: Kota Jakarta Pusat | F32: BGR | G32: Jl. Selangit Kav. 4, Gn. Sahari Sel., Kec. Kemayoran, Kota Jakarta Pusat 10620 | H32: 02122602525 | I32: farmasikemayoran.hermina@gmail.com | J32: 01.364.468.7-046.000 | K32: active | L32: =IF(F32="","",IFERROR(INDEX('8_Office'!$B$3:$B$15,MATCH(F32,'8_Office'!$A$3:$A$15,0)),"⚠ Kode tidak ditemukan")) -> Rizqullah Mediska Indonesia
A33: H021 | B33: RS HERMINA KENDARI | C33: RS Swasta | D33: Hermina | E33: Kota Kendari | F33: BGR | G33: Jl. DI Panjaitan, Wundudopi, Kec. Baruga, Kota Kendari, Sulawesi Tenggara 93117 | H33: 04013192525 | I33: keuangan.kendari@herminahospitals.com | J33: 84.671.659.5.811.000 | K33: active | L33: =IF(F33="","",IFERROR(INDEX('8_Office'!$B$3:$B$15,MATCH(F33,'8_Office'!$A$3:$A$15,0)),"⚠ Kode tidak ditemukan")) -> Rizqullah Mediska Indonesia
A34: H022 | B34: RS HERMINA KUTABUMI / PERIUK TANGERANG | C34: RS Swasta | D34: Hermina | E34: Kota Tangerang | F34: TGR | G34: Jl. Moh. Toha, Nagrak, Kec. Periuk, Kota Tangerang, Banten 15131 | H34: 02129432525 | J34: 85.048.181.3-402.000 | K34: active | L34: =IF(F34="","",IFERROR(INDEX('8_Office'!$B$3:$B$15,MATCH(F34,'8_Office'!$A$3:$A$15,0)),"⚠ Kode tidak ditemukan")) -> Rizqullah Mediska Indonesia Tangerang
A35: H023 | B35: RS HERMINA LAMPUNG | C35: RS Swasta | D35: Hermina | E35: Kota Bandar Lampung | F35: BGR | G35: Jl. Tulang Bawang No.21-23, Enggal, Kota Bandar Lampung, Lampung 35213 | H35: 0721242525 | I35: jangmed.lampung@herminahospitals.com | J35: 08.648.072.7.632.2.00 | K35: active | L35: =IF(F35="","",IFERROR(INDEX('8_Office'!$B$3:$B$15,MATCH(F35,'8_Office'!$A$3:$A$15,0)),"⚠ Kode tidak ditemukan")) -> Rizqullah Mediska Indonesia
A36: H024 | B36: RS HERMINA MADIUN | C36: RS Swasta | D36: Hermina | E36: Kota Madiun | F36: SLO | G36: Jl. Sido Makmur Jl. Ring Road Barat, Manguharjo, Kec. Manguharjo, Kota Madiun 63127 | H36: 03514108585 | I36: farmasi.hermina49@gmail.com | J36: 94.070.566.8-532.000 | K36: active | L36: =IF(F36="","",IFERROR(INDEX('8_Office'!$B$3:$B$15,MATCH(F36,'8_Office'!$A$3:$A$15,0)),"⚠ Kode tidak ditemukan")) -> Rizqullah Mediska Indonesia Jawa Tengah (Solo)
A37: H025 | B37: RS HERMINA MAKASSAR | C37: RS Swasta | D37: Hermina | E37: Kota Makassar | F37: BGR | G37: Jl. Toddopuli Raya Timur No.7, Borong, Kec. Manggala, Kota Makassar, Sulawesi Selatan 90231 | H37: 04114091817 | J37: 73.472.002.2.805.000 | K37: active | L37: =IF(F37="","",IFERROR(INDEX('8_Office'!$B$3:$B$15,MATCH(F37,'8_Office'!$A$3:$A$15,0)),"⚠ Kode tidak ditemukan")) -> Rizqullah Mediska Indonesia
A38: H026 | B38: RS HERMINA MANADO | C38: RS Swasta | D38: Hermina | E38: Kota Manado | F38: BGR | G38: Jl. Ring Road Manado II, Paniki Bawah, Kec. Mapanget, Kota Manado, Sulawesi Utara | H38: 04317242525 | I38: farmasi.manado@herminahospitals.com | J38: 82.392.404.882.1.000 | K38: active | L38: =IF(F38="","",IFERROR(INDEX('8_Office'!$B$3:$B$15,MATCH(F38,'8_Office'!$A$3:$A$15,0)),"⚠ Kode tidak ditemukan")) -> Rizqullah Mediska Indonesia
A39: H027 | B39: RS HERMINA MEDAN | C39: RS Swasta | D39: Hermina | E39: Kota Medan | F39: BGR | G39: Jl. Asrama, Sei Sikambing C. II, Kec. Medan Helvetia, Kota Medan, Sumatera Utara 20123 | H39: 06180862525 | I39: farmasi.medan@herminahospitals.com | J39: 75.709.650.8.124.00 | K39: active | L39: =IF(F39="","",IFERROR(INDEX('8_Office'!$B$3:$B$15,MATCH(F39,'8_Office'!$A$3:$A$15,0)),"⚠ Kode tidak ditemukan")) -> Rizqullah Mediska Indonesia
A40: H028 | B40: RS HERMINA MEKARSARI | C40: RS Swasta | D40: Hermina | E40: Kabupaten Bogor | F40: BGR | G40: Jl. Raya Cileungsi - Jonggol No.Km. 1, Cileungsi Kidul, Kec. Cileungsi, Kab. Bogor 16820 | H40: 02129232525 | I40: farmasi.mekarsari@herminahospitals.com | J40: 31.417.132.3.436.000 | K40: active | L40: =IF(F40="","",IFERROR(INDEX('8_Office'!$B$3:$B$15,MATCH(F40,'8_Office'!$A$3:$A$15,0)),"⚠ Kode tidak ditemukan")) -> Rizqullah Mediska Indonesia
...

Sheet 4_Products
A1: ⚠ Data kuning = produk awal/sample. manufacture_code: pilih dari dropdown → nama principal (col D) otomatis terisi 🔒. Tambah produk baru di bawah baris biru.
A2: sku | B2: products_name | C2: manufacture_code | D2: manufacture_name | E2: category | F2: unit | G2: barcode | H2: status
A3: Kode produk unik *WAJIB* | B3: Nama produk *WAJIB* | C3: Kode principal ← pilih dari dropdown | D3: Nama principal — otomatis dari kode 🔒 | E3: BMHP = habis pakai / UnitAcc = alat | F3: Satuan (PCS, BOX, SET, dll) | G3: Barcode / EAN produk (opsional) | H3: active / inactive / draft / pending_reg
A4: OBT-001 | B4: Obat A | D4: =IF(C4="","",IFERROR(INDEX('1_Manufactures'!$B$4:$B$503,MATCH(C4,'1_Manufactures'!$A$4:$A$503,0)),"⚠ Kode tidak ditemukan")) | E4: BMHP | F4: unit | G4: 8991234567890 | H4: active
A5: OBT-002 | B5: Obat B | D5: =IF(C5="","",IFERROR(INDEX('1_Manufactures'!$B$4:$B$503,MATCH(C5,'1_Manufactures'!$A$4:$A$503,0)),"⚠ Kode tidak ditemukan")) | E5: BMHP | F5: unit | H5: active
A6: ALK-001 | B6: Alkes A | D6: =IF(C6="","",IFERROR(INDEX('1_Manufactures'!$B$4:$B$503,MATCH(C6,'1_Manufactures'!$A$4:$A$503,0)),"⚠ Kode tidak ditemukan")) | E6: BMHP | F6: unit | H6: active
A7: ↑ Data di atas = produk awal/sample. Lengkapi atau tambah produk baru di bawah.
A8: ⬇ Tambahkan produk baru di baris berikutnya
D9: =IF(C9="","",IFERROR(INDEX('1_Manufactures'!$B$4:$B$503,MATCH(C9,'1_Manufactures'!$A$4:$A$503,0)),"⚠ Kode tidak ditemukan"))
D10: =IF(C10="","",IFERROR(INDEX('1_Manufactures'!$B$4:$B$503,MATCH(C10,'1_Manufactures'!$A$4:$A$503,0)),"⚠ Kode tidak ditemukan"))
D11: =IF(C11="","",IFERROR(INDEX('1_Manufactures'!$B$4:$B$503,MATCH(C11,'1_Manufactures'!$A$4:$A$503,0)),"⚠ Kode tidak ditemukan"))
D12: =IF(C12="","",IFERROR(INDEX('1_Manufactures'!$B$4:$B$503,MATCH(C12,'1_Manufactures'!$A$4:$A$503,0)),"⚠ Kode tidak ditemukan"))
D13: =IF(C13="","",IFERROR(INDEX('1_Manufactures'!$B$4:$B$503,MATCH(C13,'1_Manufactures'!$A$4:$A$503,0)),"⚠ Kode tidak ditemukan"))
D14: =IF(C14="","",IFERROR(INDEX('1_Manufactures'!$B$4:$B$503,MATCH(C14,'1_Manufactures'!$A$4:$A$503,0)),"⚠ Kode tidak ditemukan"))
D15: =IF(C15="","",IFERROR(INDEX('1_Manufactures'!$B$4:$B$503,MATCH(C15,'1_Manufactures'!$A$4:$A$503,0)),"⚠ Kode tidak ditemukan"))
D16: =IF(C16="","",IFERROR(INDEX('1_Manufactures'!$B$4:$B$503,MATCH(C16,'1_Manufactures'!$A$4:$A$503,0)),"⚠ Kode tidak ditemukan"))
D17: =IF(C17="","",IFERROR(INDEX('1_Manufactures'!$B$4:$B$503,MATCH(C17,'1_Manufactures'!$A$4:$A$503,0)),"⚠ Kode tidak ditemukan"))
D18: =IF(C18="","",IFERROR(INDEX('1_Manufactures'!$B$4:$B$503,MATCH(C18,'1_Manufactures'!$A$4:$A$503,0)),"⚠ Kode tidak ditemukan"))
D19: =IF(C19="","",IFERROR(INDEX('1_Manufactures'!$B$4:$B$503,MATCH(C19,'1_Manufactures'!$A$4:$A$503,0)),"⚠ Kode tidak ditemukan"))
D20: =IF(C20="","",IFERROR(INDEX('1_Manufactures'!$B$4:$B$503,MATCH(C20,'1_Manufactures'!$A$4:$A$503,0)),"⚠ Kode tidak ditemukan"))
... D503: =IF(C503="","",IFERROR(INDEX('1_Manufactures'!$B$4:$B$503,MATCH(C503,'1_Manufactures'!$A$4:$A$503,0)),"⚠ Kode tidak ditemukan"))

Sheet 5_Stock
A1: 🔗 Kolom SKU & Nama Produk otomatis terhubung (formula) ke sheet 4_Products. Tim hanya perlu mengisi qty_on_hand (kolom C) dan office_code (kolom D). Tambah produk baru di sheet 4_Products → otomatis muncul di sini.
A2: sku | B2: products_name | C2: qty_on_hand | D2: office_code
A3: Otomatis dari sheet 4_Products — 🔒 jangan diubah | B3: Otomatis dari sheet 4_Products — 🔒 jangan diubah | C3: Stok fisik per tanggal cutover ← ISI DI SINI *WAJIB* | D3: Kode office: BGR, BDG, BKS, TGR, SLO, SMG, JGY, KAL
A4: =IF('4_Products'!A4="","",'4_Products'!A4) -> OBT-001 | B4: =IF('4_Products'!B4="","",'4_Products'!B4) -> Obat A
A5: =IF('4_Products'!A5="","",'4_Products'!A5) -> OBT-002 | B5: =IF('4_Products'!B5="","",'4_Products'!B5) -> Obat B
A6: =IF('4_Products'!A6="","",'4_Products'!A6) -> ALK-001 | B6: =IF('4_Products'!B6="","",'4_Products'!B6) -> Alkes A
A7: =IF('4_Products'!A7="","",'4_Products'!A7) -> ↑ Data di atas = produk awal/sample. Lengkapi atau tambah produk baru di bawah. | B7: =IF('4_Products'!B7="","",'4_Products'!B7)
A8: =IF('4_Products'!A8="","",'4_Products'!A8) -> ⬇ Tambahkan produk baru di baris berikutnya | B8: =IF('4_Products'!B8="","",'4_Products'!B8)
A9: =IF('4_Products'!A9="","",'4_Products'!A9) | B9: =IF('4_Products'!B9="","",'4_Products'!B9)
A10: =IF('4_Products'!A10="","",'4_Products'!A10) | B10: =IF('4_Products'!B10="","",'4_Products'!B10)
A11: =IF('4_Products'!A11="","",'4_Products'!A11) | B11: =IF('4_Products'!B11="","",'4_Products'!B11)
A12: =IF('4_Products'!A12="","",'4_Products'!A12) | B12: =IF('4_Products'!B12="","",'4_Products'!B12)
A13: =IF('4_Products'!A13="","",'4_Products'!A13) | B13: =IF('4_Products'!B13="","",'4_Products'!B13)
A14: =IF('4_Products'!A14="","",'4_Products'!A14) | B14: =IF('4_Products'!B14="","",'4_Products'!B14)
A15: =IF('4_Products'!A15="","",'4_Products'!A15) | B15: =IF('4_Products'!B15="","",'4_Products'!B15)
... A503: =IF('4_Products'!A503="","",'4_Products'!A503) | B503: =IF('4_Products'!B503="","",'4_Products'!B503)
A506: 📊 RINGKASAN — hanya untuk verifikasi, tidak diupload
A507: Produk dengan stok (qty > 0) : | B507: =COUNTIF(C4:C503,">"&0) -> 0
A508: Total qty keseluruhan : | B508: =SUM(C4:C503) -> 0

Sheet 6_AP
A1: ⚙ Hutang ke principal. manufacture_code: pilih dari dropdown → nama principal (col E) otomatis 🔒. Tanggal format: YYYY-MM-DD. Kolom migration_batch & row_no otomatis.
A2: invoice_number | B2: invoice_date | C2: due_date | D2: manufacture_code | E2: manufacture_name | F2: office_code | G2: currency | H2: balance_amount | I2: note
A3: No. invoice hutang *WAJIB* | B3: Tanggal invoice (YYYY-MM-DD) *WAJIB* | C3: Tanggal jatuh tempo (YYYY-MM-DD) | D3: Kode principal ← pilih dari dropdown *WAJIB* | E3: Nama principal — otomatis dari kode 🔒 | F3: Kode office (BGR, BDG, dst) | G3: IDR / USD / CNY / EUR / SGD | H3: Saldo hutang per cutover *WAJIB* | I3: Catatan (opsional)
A4: INV-AP-2026-001 | B4: 2026-01-31 | C4: 2026-02-28 | D4: YAXIN | E4: =IF(D4="","",IFERROR(INDEX('1_Manufactures'!$B$4:$B$503,MATCH(D4,'1_Manufactures'!$A$4:$A$503,0)),"⚠ Kode tidak ditemukan")) -> Suzhou Yaxin Medical Products Co., Ltd | F4: BGR | G4: IDR | H4: 12500000 | I4: Hutang opening cutover
A5: INV-AP-2026-002 | B5: 2026-01-15 | C5: 2026-02-15 | D5: CATHAY | E5: =IF(D5="","",IFERROR(INDEX('1_Manufactures'!$B$4:$B$503,MATCH(D5,'1_Manufactures'!$A$4:$A$503,0)),"⚠ Kode tidak ditemukan")) -> CATHAY MANUFACTURING CORP | F5: BGR | G5: USD | H5: 5000 | I5: Hutang USD opening
E6: =IF(D6="","",IFERROR(INDEX('1_Manufactures'!$B$4:$B$503,MATCH(D6,'1_Manufactures'!$A$4:$A$503,0)),"⚠ Kode tidak ditemukan"))
E7: =IF(D7="","",IFERROR(INDEX('1_Manufactures'!$B$4:$B$503,MATCH(D7,'1_Manufactures'!$A$4:$A$503,0)),"⚠ Kode tidak ditemukan"))
E8: =IF(D8="","",IFERROR(INDEX('1_Manufactures'!$B$4:$B$503,MATCH(D8,'1_Manufactures'!$A$4:$A$503,0)),"⚠ Kode tidak ditemukan"))
E9: =IF(D9="","",IFERROR(INDEX('1_Manufactures'!$B$4:$B$503,MATCH(D9,'1_Manufactures'!$A$4:$A$503,0)),"⚠ Kode tidak ditemukan"))
E10: =IF(D10="","",IFERROR(INDEX('1_Manufactures'!$B$4:$B$503,MATCH(D10,'1_Manufactures'!$A$4:$A$503,0)),"⚠ Kode tidak ditemukan"))
E11: =IF(D11="","",IFERROR(INDEX('1_Manufactures'!$B$4:$B$503,MATCH(D11,'1_Manufactures'!$A$4:$A$503,0)),"⚠ Kode tidak ditemukan"))
E12: =IF(D12="","",IFERROR(INDEX('1_Manufactures'!$B$4:$B$503,MATCH(D12,'1_Manufactures'!$A$4:$A$503,0)),"⚠ Kode tidak ditemukan"))
E13: =IF(D13="","",IFERROR(INDEX('1_Manufactures'!$B$4:$B$503,MATCH(D13,'1_Manufactures'!$A$4:$A$503,0)),"⚠ Kode tidak ditemukan"))
E14: =IF(D14="","",IFERROR(INDEX('1_Manufactures'!$B$4:$B$503,MATCH(D14,'1_Manufactures'!$A$4:$A$503,0)),"⚠ Kode tidak ditemukan"))
E15: =IF(D15="","",IFERROR(INDEX('1_Manufactures'!$B$4:$B$503,MATCH(D15,'1_Manufactures'!$A$4:$A$503,0)),"⚠ Kode tidak ditemukan"))
E16: =IF(D16="","",IFERROR(INDEX('1_Manufactures'!$B$4:$B$503,MATCH(D16,'1_Manufactures'!$A$4:$A$503,0)),"⚠ Kode tidak ditemukan"))
E17: =IF(D17="","",IFERROR(INDEX('1_Manufactures'!$B$4:$B$503,MATCH(D17,'1_Manufactures'!$A$4:$A$503,0)),"⚠ Kode tidak ditemukan"))
... E503: =IF(D503="","",IFERROR(INDEX('1_Manufactures'!$B$4:$B$503,MATCH(D503,'1_Manufactures'!$A$4:$A$503,0)),"⚠ Kode tidak ditemukan"))
A506: 📊 RINGKASAN — hanya untuk verifikasi, tidak diupload
A507: Total invoice hutang : | B507: =COUNTA(A4:A503) -> 2
A508: Total balance (semua currency) : | B508: =SUM(H4:H503) -> 12505000

Sheet 7_AR
A1: ⚙ Piutang dari customer. customers_code: pilih dari dropdown → nama customer (col E) otomatis 🔒. Tanggal format: YYYY-MM-DD. Kolom migration_batch & row_no otomatis.
A2: invoice_number | B2: invoice_date | C2: due_date | D2: customers_code | E2: customers_name | F2: office_code | G2: currency | H2: balance_amount | I2: note
A3: No. invoice piutang *WAJIB* | B3: Tanggal invoice (YYYY-MM-DD) *WAJIB* | C3: Tanggal jatuh tempo (YYYY-MM-DD) | D3: Kode customer ← pilih dari dropdown *WAJIB* | E3: Nama customer — otomatis dari kode 🔒 | F3: Kode office (BGR, BDG, dst) | G3: IDR / USD / CNY / EUR / SGD | H3: Saldo piutang per cutover *WAJIB* | I3: Catatan (opsional)
A4: INV-AR-2026-001 | B4: 2026-01-31 | C4: 2026-02-28 | D4: H001 | E4: =IF(D4="","",IFERROR(INDEX('3_Customers'!$B$4:$B$503,MATCH(D4,'3_Customers'!$A$4:$A$503,0)),"⚠ Kode tidak ditemukan")) -> RS HERMINA ACEH | F4: BGR | G4: IDR | H4: 9800000 | I4: Piutang opening cutover
A5: INV-AR-2026-002 | B5: 2026-01-20 | C5: 2026-02-20 | D5: H007 | E5: =IF(D5="","",IFERROR(INDEX('3_Customers'!$B$4:$B$503,MATCH(D5,'3_Customers'!$A$4:$A$503,0)),"⚠ Kode tidak ditemukan")) -> RS HERMINA BOGOR | F5: BGR | G5: IDR | H5: 5500000 | I5: Piutang opening cutover
E6: =IF(D6="","",IFERROR(INDEX('3_Customers'!$B$4:$B$503,MATCH(D6,'3_Customers'!$A$4:$A$503,0)),"⚠ Kode tidak ditemukan"))
E7: =IF(D7="","",IFERROR(INDEX('3_Customers'!$B$4:$B$503,MATCH(D7,'3_Customers'!$A$4:$A$503,0)),"⚠ Kode tidak ditemukan"))
E8: =IF(D8="","",IFERROR(INDEX('3_Customers'!$B$4:$B$503,MATCH(D8,'3_Customers'!$A$4:$A$503,0)),"⚠ Kode tidak ditemukan"))
E9: =IF(D9="","",IFERROR(INDEX('3_Customers'!$B$4:$B$503,MATCH(D9,'3_Customers'!$A$4:$A$503,0)),"⚠ Kode tidak ditemukan"))
E10: =IF(D10="","",IFERROR(INDEX('3_Customers'!$B$4:$B$503,MATCH(D10,'3_Customers'!$A$4:$A$503,0)),"⚠ Kode tidak ditemukan"))
E11: =IF(D11="","",IFERROR(INDEX('3_Customers'!$B$4:$B$503,MATCH(D11,'3_Customers'!$A$4:$A$503,0)),"⚠ Kode tidak ditemukan"))
E12: =IF(D12="","",IFERROR(INDEX('3_Customers'!$B$4:$B$503,MATCH(D12,'3_Customers'!$A$4:$A$503,0)),"⚠ Kode tidak ditemukan"))
E13: =IF(D13="","",IFERROR(INDEX('3_Customers'!$B$4:$B$503,MATCH(D13,'3_Customers'!$A$4:$A$503,0)),"⚠ Kode tidak ditemukan"))
E14: =IF(D14="","",IFERROR(INDEX('3_Customers'!$B$4:$B$503,MATCH(D14,'3_Customers'!$A$4:$A$503,0)),"⚠ Kode tidak ditemukan"))
E15: =IF(D15="","",IFERROR(INDEX('3_Customers'!$B$4:$B$503,MATCH(D15,'3_Customers'!$A$4:$A$503,0)),"⚠ Kode tidak ditemukan"))
E16: =IF(D16="","",IFERROR(INDEX('3_Customers'!$B$4:$B$503,MATCH(D16,'3_Customers'!$A$4:$A$503,0)),"⚠ Kode tidak ditemukan"))
E17: =IF(D17="","",IFERROR(INDEX('3_Customers'!$B$4:$B$503,MATCH(D17,'3_Customers'!$A$4:$A$503,0)),"⚠ Kode tidak ditemukan"))
... E503: =IF(D503="","",IFERROR(INDEX('3_Customers'!$B$4:$B$503,MATCH(D503,'3_Customers'!$A$4:$A$503,0)),"⚠ Kode tidak ditemukan"))
A506: 📊 RINGKASAN — hanya untuk verifikasi, tidak diupload
A507: Total invoice piutang : | B507: =COUNTA(A4:A503) -> 2
A508: Total balance (semua currency) : | B508: =SUM(H4:H503) -> 15300000

Sheet 8_Office
A1: office_code | B1: office_name | C1: office_lat | D1: office_lng | E1: office_radius_m | F1: status
A2: Kode office (BGR, BDG, dll) | B2: Nama kantor/depo | C2: Latitude GPS (contoh: -6.597147) | D2: Longitude GPS (contoh: 106.806039) | E2: Radius absensi geofence (meter) | F2: active / inactive
A3: BGR | B3: Rizqullah Mediska Indonesia | C3: -6.597147 | D3: 106.80604 | E3: 150 | F3: active
A4: BKS | B4: Rizqullah Mediska Indonesia Bekasi | C4: -6.23827 | D4: 106.97557 | E4: 150 | F4: active
A5: TGR | B5: Rizqullah Mediska Indonesia Tangerang | C5: -6.178306 | D5: 106.63189 | E5: 150 | F5: active
A6: BDG | B6: Rizqullah Mediska Indonesia Bandung | C6: -6.917464 | D6: 107.61912 | E6: 150 | F6: active
A7: SLO | B7: Rizqullah Mediska Indonesia Jawa Tengah (Solo) | C7: -7.566667 | D7: 110.81667 | E7: 150 | F7: active
A8: SMG | B8: Rizqullah Mediska Indonesia Semarang | C8: -6.966667 | D8: 110.41667 | E8: 150 | F8: active
A9: KAL | B9: Depo Kalimantan | E9: 120 | F9: active
A10: JGY | B10: Depo Yogyakarta | E10: 120 | F10: active
A11: SYS | B11: SYS | E11: 120 | F11: inactive
A12: ⚠ Sheet ini untuk UPDATE office yang sudah ada. Jika ingin tambah office baru, hubungi Administrator ITC.

Sheet 9_Bank
A1: bank_name | B1: account_name | C1: account_number | D1: currency | E1: office_code | F1: balance_date | G1: balance_amount | H1: note
A2: Nama bank (BCA, Mandiri, BRI, dll) | B2: Nama pemilik rekening | C2: Nomor rekening | D2: IDR / USD / CNY | E2: Kode office (BGR, BDG, dll) | F2: Tanggal saldo (YYYY-MM-DD) | G2: Saldo rekening | H2: Catatan
A3: BCA | B3: PT Rizqullah Mediska Indonesia | C3: 1234567890 | D3: IDR | E3: BGR | F3: 2026-01-31 | G3: 500000000 | H3: Rekening operasional
A4: Mandiri | B4: PT Rizqullah Mediska Indonesia | C4: 0987654321 | D4: IDR | E4: BGR | F4: 2026-01-31 | G4: 250000000 | H4: Rekening tabungan
A5: ⚠ Sheet ini COMING SOON — belum diproses sistem saat ini.

Sheet 10_GL_Opening
A1: account_code | B1: account_name | C1: debit | D1: credit | E1: note
A2: Kode akun GL | B2: Nama akun | C2: Jumlah debit | D2: Jumlah kredit | E2: Catatan
A3: 1100 | B3: Kas | C3: 100000000 | D3: 0 | E3: Opening balance
A4: 1200 | B4: Bank | C4: 500000000 | D4: 0 | E4: Opening balance
A5: 2100 | B5: Hutang Usaha | C5: 0 | D5: 50000000 | E5: Opening balance
A6: ⚠ Sheet ini COMING SOON — belum diproses sistem saat ini.

Sheet 11_FixedAssets
A1: asset_code | B1: asset_name | C1: category | D1: acquisition_date | E1: acquisition_value | F1: office_code | G1: note
A2: Kode aset unik | B2: Nama aset | C2: IT / Kendaraan / Bangunan / Peralatan | D2: Tanggal perolehan (YYYY-MM-DD) | E2: Nilai perolehan (Rp) | F2: Kode office (BGR, BDG, dll) | G2: Catatan
A3: FA-BGR-001 | B3: Laptop Dell Latitude 5520 | C3: IT | D3: 2025-01-15 | E3: 15000000 | F3: BGR | G3: Opening
A4: FA-BGR-002 | B4: Mobil Toyota Kijang Innova | C4: Kendaraan | D4: 2024-06-01 | E4: 320000000 | F4: BGR | G4: Opening
A5: ⚠ Sheet ini COMING SOON — belum diproses sistem saat ini.

Sheet 12_Cara_Pengisian
A1: PANDUAN PENGISIAN — RMI Migration Template
A2: 🔴 Kolom merah = WAJIB diisi | C2: 🟡 Baris kuning = contoh isian (hapus sebelum upload jika sudah punya data sendiri)
A3: Sheet | B3: Urutan | C3: Cara Pengisian | D3: Valid Values / Dropdown | E3: Status
A4: 1_Manufactures | B4: 1 | C4: Isi principal dari sistem lama. manufacture_code harus unik. Wajib sebelum Products. | D4: origin_type: Local, Import status: active, inactive | E4: Diproses
A5: 2_Vendors | B5: 2 | C5: Vendor logistik/forwarding. vendors_code harus unik. Opsional. | D5: vendor_type: Forwarding, Logistic, Lainnya category: ACT,CRM,SCM,WQS,FIN,HRL,PQP,ITC,MPR status: active, inactive | E5: Diproses
A6: 3_Customers | B6: 3 | C6: Customer RS/Klinik/Internal. customers_code harus unik. Wajib sebelum AR. | D6: category: RS Swasta, RS Pemerintah, Internal segment: Hermina, Non Hermina, RSUD, Kantor office_code: BGR,BDG,BKS,TGR,SLO,SMG,JGY,KAL status: active, inactive | E6: Diproses
A7: 4_Products | B7: 4 | C7: Produk/item. SKU harus unik. manufacture_code harus ada di sheet 1. Wajib sebelum Stock. | D7: category: BMHP, UnitAcc unit: PCS,BOX,SET,UNIT,PAIR,ROLL,PACK,dll status: active, inactive, draft, pending_reg | E7: Diproses
A8: 5_Stock | B8: 5 | C8: Stok fisik per SKU per office. SKU harus ada di master_products. Kolom batch & row_no otomatis. | D8: office_code: BGR,BDG,BKS,TGR,SLO,SMG,JGY,KAL | E8: Diproses
A9: 6_AP | B9: 6 | C9: Hutang ke principal (opening balance). manufacture_code harus ada di sheet 1. Tanggal format YYYY-MM-DD. Kolom batch & row_no otomatis. | D9: office_code: BGR,BDG,... currency: IDR,USD,CNY,EUR,SGD | E9: Diproses
A10: 7_AR | B10: 7 | C10: Piutang dari customer (opening balance). customers_code harus ada di sheet 3. Tanggal format YYYY-MM-DD. Kolom batch & row_no otomatis. | D10: office_code: BGR,BDG,... currency: IDR,USD,CNY,EUR,SGD | E10: Diproses
A11: 8_Office | B11: 8 | C11: Update data office yang sudah ada. Tidak bisa menambah office baru dari sini. | D11: office_code: BGR,BDG,BKS,TGR,SLO,SMG,JGY,KAL | E11: Diproses
A12: 9_Bank | B12: 9 | C12: Saldo rekening bank opening. Tidak wajib. | D12: currency: IDR,USD,CNY office_code: BGR,BDG,... | E12: Coming Soon
A13: 10_GL_Opening | B13: 10 | C13: Jurnal saldo awal akuntansi. Tidak wajib. | D13: - | E13: Coming Soon
A14: 11_FixedAssets | B14: 11 | C14: Daftar aset tetap opening. Tidak wajib. | D14: category: IT,Kendaraan,Bangunan,Peralatan,Furniture,Lainnya office_code: BGR,BDG,... | E14: Coming Soon
A15: 12_Cara_Pengisian | B15: - | C15: Sheet panduan ini. Jangan dihapus. | D15: - | E15: -
A16: REF_ValidValues | B16: - | C16: Daftar referensi nilai valid semua kolom dropdown. | D16: - | E16: -
A18: TIPS:
A19: 1. Isi sheet sesuai URUTAN (1 → 4 master dulu, baru 5 → 7 transaksi).
A20: 2. Hapus baris contoh (kuning) sebelum upload jika data kamu sudah ada.
A21: 3. Jangan ubah nama sheet dan header kolom.
A22: 4. Tanggal di sheet 6_AP dan 7_AR HARUS format YYYY-MM-DD (contoh: 2026-01-31).
A23: 5. Kolom dengan nama merah = WAJIB. Kosong = baris di-skip.
A24: 6. Jika ada error saat upload, pesan error muncul di halaman upload.

Sheet REF_ValidValues
A1: REF — Valid Values Semua Dropdown
A2: Sheet | B2: Kolom | C2: Valid Values | D2: Keterangan
A3: 1_Manufactures | B3: origin_type | C3: Local, Import | D3: Asal barang
A4: 1_Manufactures | B4: status | C4: active, inactive | D4: Status principal
A5: 2_Vendors | B5: vendor_type | C5: Forwarding, Logistic, Lainnya | D5: Tipe vendor
A6: 2_Vendors | B6: category | C6: ACT, CRM, SCM, WQS, FIN, HRL, PQP, ITC, MPR | D6: Departemen terkait
A7: 2_Vendors | B7: status | C7: active, inactive | D7: Status vendor
A8: 3_Customers | B8: category | C8: RS Swasta, RS Pemerintah, Internal | D8: Kategori customer
A9: 3_Customers | B9: segment | C9: Hermina, Non Hermina, RSUD, Kantor | D9: Segmen customer
A10: 3_Customers | B10: office_code | C10: BGR, BDG, BKS, TGR, SLO, SMG, JGY, KAL | D10: Kode kantor/depo
A11: 3_Customers | B11: status | C11: active, inactive | D11: Status customer
A12: 4_Products | B12: category | C12: BMHP, UnitAcc | D12: BMHP = habis pakai; UnitAcc = alat/peralatan
A13: 4_Products | B13: unit | C13: PCS, BOX, SET, UNIT, PAIR, ROLL, PACK, TUBE, VIAL, AMPUL, BOTOL, STRIP, KAPSUL, TABLET, LITER, ML, GRAM, KG | D13: Satuan produk
... A21: 8_Office | B21: status | C21: active, inactive | D21: Status office
A23: Office Code | B23: Kota
A24: BGR | B24: Bogor
A25: BDG | B25: Bandung
A26: BKS | B26: Bekasi
A27: TGR | B27: Tangerang
A28: SLO | B28: Solo
A29: SMG | B29: Semarang
A30: JGY | B30: Yogyakarta
A31: KAL | B31: Kalimantan
A32: SYS | B32: System (admin)
